Workbook

Sheet 26년 월마감
B2: 삼양이엔지 일일 품질현황 (2026년 06월) | U2: 작성 | V2: 검토 | W2: 승인
B6: 회사명 | C6: 모델 | E6: 작업수량 | F6: 양품 | G6: 불량 | H6: 불량율 | I6: 불량내역
I7: S/C | J7: 찍힘 | K7: A/D얼룩 | L7: H/L | M7: 휨 | O7: 기포 | P7: 소재 | Q7: 툴자국 | R7: 가공 | U7: 이물 | V7: 코팅얼룩 | W7: 시료
B8: 삼양 | C8: 61MM | D8: KA4 | E8: =+'1'!AD5+'2'!AD5+'3'!AD5+'4'!AD5+'5'!AD5+'6'!AD5+'7'!AD5+'8'!AD5+'9'!AD5+'10'!AD5+'11'!AD5+'12'!AD5+'13'!AD5+'14'!AD5+'15'!AD5+'16'!AD5+'17'!AD5+'18'!AD5+'19'!AD5+'20'!AD5+'21'!AD5+'22'!AD5+'23'!AD5+'24'!AD5+'25'!AD5+'26'!AD5+'27'!AD5+'28'!AD5+'29'!AD5+'30'!AD5+'31'!AD5 -> 0 | F8: =+'1'!AE5+'2'!AE5+'3'!AE5+'4'!AE5+'5'!AE5+'6'!AE5+'7'!AE5+'8'!AE5+'9'!AE5+'10'!AE5+'11'!AE5+'12'!AE5+'13'!AE5+'14'!AE5+'15'!AE5+'16'!AE5+'17'!AE5+'18'!AE5+'19'!AE5+'20'!AE5+'21'!AE5+'22'!AE5+'23'!AE5+'24'!AE5+'25'!AE5+'26'!AE5+'27'!AE5+'28'!AE5+'29'!AE5+'30'!AE5+'31'!AE5 -> 0 | G8: =+'1'!AF5+'2'!AF5+'3'!AF5+'4'!AF5+'5'!AF5+'6'!AF5+'7'!AF5+'8'!AF5+'9'!AF5+'10'!AF5+'11'!AF5+'12'!AF5+'13'!AF5+'14'!AF5+'15'!AF5+'16'!AF5+'17'!AF5+'18'!AF5+'19'!AF5+'20'!AF5+'21'!AF5+'22'!AF5+'23'!AF5+'24'!AF5+'25'!AF5+'26'!AF5+'27'!AF5+'28'!AF5+'29'!AF5+'30'!AF5+'31'!AF5 -> 0 | H8: =IF(E8=0,"",G8/E8) | I8: =+'1'!AH5+'2'!AH5+'3'!AH5+'4'!AH5+'5'!AH5+'6'!AH5+'7'!AH5+'8'!AH5+'9'!AH5+'10'!AH5+'11'!AH5+'12'!AH5+'13'!AH5+'14'!AH5+'15'!AH5+'16'!AH5+'17'!AH5+'18'!AH5+'19'!AH5+'20'!AH5+'21'!AH5+'22'!AH5+'23'!AH5+'24'!AH5+'25'!AH5+'26'!AH5+'27'!AH5+'28'!AH5+'29'!AH5+'30'!AH5+'31'!AH5 -> 0 | J8: =+'1'!AI5+'2'!AI5+'3'!AI5+'4'!AI5+'5'!AI5+'6'!AI5+'7'!AI5+'8'!AI5+'9'!AI5+'10'!AI5+'11'!AI5+'12'!AI5+'13'!AI5+'14'!AI5+'15'!AI5+'16'!AI5+'17'!AI5+'18'!AI5+'19'!AI5+'20'!AI5+'21'!AI5+'22'!AI5+'23'!AI5+'24'!AI5+'25'!AI5+'26'!AI5+'27'!AI5+'28'!AI5+'29'!AI5+'30'!AI5+'31'!AI5 -> 0 | K8: =+'1'!AJ5+'2'!AJ5+'3'!AJ5+'4'!AJ5+'5'!AJ5+'6'!AJ5+'7'!AJ5+'8'!AJ5+'9'!AJ5+'10'!AJ5+'11'!AJ5+'12'!AJ5+'13'!AJ5+'14'!AJ5+'15'!AJ5+'16'!AJ5+'17'!AJ5+'18'!AJ5+'19'!AJ5+'20'!AJ5+'21'!AJ5+'22'!AJ5+'23'!AJ5+'24'!AJ5+'25'!AJ5+'26'!AJ5+'27'!AJ5+'28'!AJ5+'29'!AJ5+'30'!AJ5+'31'!AJ5 -> 0 | L8: =+'1'!AK5+'2'!AK5+'3'!AK5+'4'!AK5+'5'!AK5+'6'!AK5+'7'!AK5+'8'!AK5+'9'!AK5+'10'!AK5+'11'!AK5+'12'!AK5+'13'!AK5+'14'!AK5+'15'!AK5+'16'!AK5+'17'!AK5+'18'!AK5+'19'!AK5+'20'!AK5+'21'!AK5+'22'!AK5+'23'!AK5+'24'!AK5+'25'!AK5+'26'!AK5+'27'!AK5+'28'!AK5+'29'!AK5+'30'!AK5+'31'!AK5 -> 0 | M8: =+'1'!AL5+'2'!AL5+'3'!AL5+'4'!AL5+'5'!AL5+'6'!AL5+'7'!AL5+'8'!AL5+'9'!AL5+'10'!AL5+'11'!AL5+'12'!AL5+'13'!AL5+'14'!AL5+'15'!AL5+'16'!AL5+'17'!AL5+'18'!AL5+'19'!AL5+'20'!AL5+'21'!AL5+'22'!AL5+'23'!AL5+'24'!AL5+'25'!AL5+'26'!AL5+'27'!AL5+'28'!AL5+'29'!AL5+'30'!AL5+'31'!AL5 -> 0 | N8: =+'1'!AM5+'2'!AM5+'3'!AM5+'4'!AM5+'5'!AM5+'6'!AM5+'7'!AM5+'8'!AM5+'9'!AM5+'10'!AM5+'11'!AM5+'12'!AM5+'13'!AM5+'14'!AM5+'15'!AM5+'16'!AM5+'17'!AM5+'18'!AM5+'19'!AM5+'20'!AM5+'21'!AM5+'22'!AM5+'23'!AM5+'24'!AM5+'25'!AM5+'26'!AM5+'27'!AM5+'28'!AM5+'29'!AM5+'30'!AM5+'31'!AM5 -> 0 | O8: =+'1'!AN5+'2'!AN5+'3'!AN5+'4'!AN5+'5'!AN5+'6'!AN5+'7'!AN5+'8'!AN5+'9'!AN5+'10'!AN5+'11'!AN5+'12'!AN5+'13'!AN5+'14'!AN5+'15'!AN5+'16'!AN5+'17'!AN5+'18'!AN5+'19'!AN5+'20'!AN5+'21'!AN5+'22'!AN5+'23'!AN5+'24'!AN5+'25'!AN5+'26'!AN5+'27'!AN5+'28'!AN5+'29'!AN5+'30'!AN5+'31'!AN5 -> 0 | P8: =+'1'!AO5+'2'!AO5+'3'!AO5+'4'!AO5+'5'!AO5+'6'!AO5+'7'!AO5+'8'!AO5+'9'!AO5+'10'!AO5+'11'!AO5+'12'!AO5+'13'!AO5+'14'!AO5+'15'!AO5+'16'!AO5+'17'!AO5+'18'!AO5+'19'!AO5+'20'!AO5+'21'!AO5+'22'!AO5+'23'!AO5+'24'!AO5+'25'!AO5+'26'!AO5+'27'!AO5+'28'!AO5+'29'!AO5+'30'!AO5+'31'!AO5 -> 0 | ... W8: =+'1'!AV5+'2'!AV5+'3'!AV5+'4'!AV5+'5'!AV5+'6'!AV5+'7'!AV5+'8'!AV5+'9'!AV5+'10'!AV5+'11'!AV5+'12'!AV5+'13'!AV5+'14'!AV5+'15'!AV5+'16'!AV5+'17'!AV5+'18'!AV5+'19'!AV5+'20'!AV5+'21'!AV5+'22'!AV5+'23'!AV5+'24'!AV5+'25'!AV5+'26'!AV5+'27'!AV5+'28'!AV5+'29'!AV5+'30'!AV5+'31'!AV5 -> 0
C9: 71MM | D9: GL3 | E9: =+'1'!AD6+'2'!AD6+'3'!AD6+'4'!AD6+'5'!AD6+'6'!AD6+'7'!AD6+'8'!AD6+'9'!AD6+'10'!AD6+'11'!AD6+'12'!AD6+'13'!AD6+'14'!AD6+'15'!AD6+'16'!AD6+'17'!AD6+'18'!AD6+'19'!AD6+'20'!AD6+'21'!AD6+'22'!AD6+'23'!AD6+'24'!AD6+'25'!AD6+'26'!AD6+'27'!AD6+'28'!AD6+'29'!AD6+'30'!AD6+'31'!AD6 -> 0 | F9: =+'1'!AE6+'2'!AE6+'3'!AE6+'4'!AE6+'5'!AE6+'6'!AE6+'7'!AE6+'8'!AE6+'9'!AE6+'10'!AE6+'11'!AE6+'12'!AE6+'13'!AE6+'14'!AE6+'15'!AE6+'16'!AE6+'17'!AE6+'18'!AE6+'19'!AE6+'20'!AE6+'21'!AE6+'22'!AE6+'23'!AE6+'24'!AE6+'25'!AE6+'26'!AE6+'27'!AE6+'28'!AE6+'29'!AE6+'30'!AE6+'31'!AE6 -> 0 | G9: =+'1'!AF6+'2'!AF6+'3'!AF6+'4'!AF6+'5'!AF6+'6'!AF6+'7'!AF6+'8'!AF6+'9'!AF6+'10'!AF6+'11'!AF6+'12'!AF6+'13'!AF6+'14'!AF6+'15'!AF6+'16'!AF6+'17'!AF6+'18'!AF6+'19'!AF6+'20'!AF6+'21'!AF6+'22'!AF6+'23'!AF6+'24'!AF6+'25'!AF6+'26'!AF6+'27'!AF6+'28'!AF6+'29'!AF6+'30'!AF6+'31'!AF6 -> 0 | H9: =IF(E9=0,"",G9/E9) | I9: =+'1'!AH6+'2'!AH6+'3'!AH6+'4'!AH6+'5'!AH6+'6'!AH6+'7'!AH6+'8'!AH6+'9'!AH6+'10'!AH6+'11'!AH6+'12'!AH6+'13'!AH6+'14'!AH6+'15'!AH6+'16'!AH6+'17'!AH6+'18'!AH6+'19'!AH6+'20'!AH6+'21'!AH6+'22'!AH6+'23'!AH6+'24'!AH6+'25'!AH6+'26'!AH6+'27'!AH6+'28'!AH6+'29'!AH6+'30'!AH6+'31'!AH6 -> 0 | J9: =+'1'!AI6+'2'!AI6+'3'!AI6+'4'!AI6+'5'!AI6+'6'!AI6+'7'!AI6+'8'!AI6+'9'!AI6+'10'!AI6+'11'!AI6+'12'!AI6+'13'!AI6+'14'!AI6+'15'!AI6+'16'!AI6+'17'!AI6+'18'!AI6+'19'!AI6+'20'!AI6+'21'!AI6+'22'!AI6+'23'!AI6+'24'!AI6+'25'!AI6+'26'!AI6+'27'!AI6+'28'!AI6+'29'!AI6+'30'!AI6+'31'!AI6 -> 0 | K9: =+'1'!AJ6+'2'!AJ6+'3'!AJ6+'4'!AJ6+'5'!AJ6+'6'!AJ6+'7'!AJ6+'8'!AJ6+'9'!AJ6+'10'!AJ6+'11'!AJ6+'12'!AJ6+'13'!AJ6+'14'!AJ6+'15'!AJ6+'16'!AJ6+'17'!AJ6+'18'!AJ6+'19'!AJ6+'20'!AJ6+'21'!AJ6+'22'!AJ6+'23'!AJ6+'24'!AJ6+'25'!AJ6+'26'!AJ6+'27'!AJ6+'28'!AJ6+'29'!AJ6+'30'!AJ6+'31'!AJ6 -> 0 | L9: =+'1'!AK6+'2'!AK6+'3'!AK6+'4'!AK6+'5'!AK6+'6'!AK6+'7'!AK6+'8'!AK6+'9'!AK6+'10'!AK6+'11'!AK6+'12'!AK6+'13'!AK6+'14'!AK6+'15'!AK6+'16'!AK6+'17'!AK6+'18'!AK6+'19'!AK6+'20'!AK6+'21'!AK6+'22'!AK6+'23'!AK6+'24'!AK6+'25'!AK6+'26'!AK6+'27'!AK6+'28'!AK6+'29'!AK6+'30'!AK6+'31'!AK6 -> 0 | M9: =+'1'!AL6+'2'!AL6+'3'!AL6+'4'!AL6+'5'!AL6+'6'!AL6+'7'!AL6+'8'!AL6+'9'!AL6+'10'!AL6+'11'!AL6+'12'!AL6+'13'!AL6+'14'!AL6+'15'!AL6+'16'!AL6+'17'!AL6+'18'!AL6+'19'!AL6+'20'!AL6+'21'!AL6+'22'!AL6+'23'!AL6+'24'!AL6+'25'!AL6+'26'!AL6+'27'!AL6+'28'!AL6+'29'!AL6+'30'!AL6+'31'!AL6 -> 0 | N9: =+'1'!AM6+'2'!AM6+'3'!AM6+'4'!AM6+'5'!AM6+'6'!AM6+'7'!AM6+'8'!AM6+'9'!AM6+'10'!AM6+'11'!AM6+'12'!AM6+'13'!AM6+'14'!AM6+'15'!AM6+'16'!AM6+'17'!AM6+'18'!AM6+'19'!AM6+'20'!AM6+'21'!AM6+'22'!AM6+'23'!AM6+'24'!AM6+'25'!AM6+'26'!AM6+'27'!AM6+'28'!AM6+'29'!AM6+'30'!AM6+'31'!AM6 -> 0 | O9: =+'1'!AN6+'2'!AN6+'3'!AN6+'4'!AN6+'5'!AN6+'6'!AN6+'7'!AN6+'8'!AN6+'9'!AN6+'10'!AN6+'11'!AN6+'12'!AN6+'13'!AN6+'14'!AN6+'15'!AN6+'16'!AN6+'17'!AN6+'18'!AN6+'19'!AN6+'20'!AN6+'21'!AN6+'22'!AN6+'23'!AN6+'24'!AN6+'25'!AN6+'26'!AN6+'27'!AN6+'28'!AN6+'29'!AN6+'30'!AN6+'31'!AN6 -> 0 | P9: =+'1'!AO6+'2'!AO6+'3'!AO6+'4'!AO6+'5'!AO6+'6'!AO6+'7'!AO6+'8'!AO6+'9'!AO6+'10'!AO6+'11'!AO6+'12'!AO6+'13'!AO6+'14'!AO6+'15'!AO6+'16'!AO6+'17'!AO6+'18'!AO6+'19'!AO6+'20'!AO6+'21'!AO6+'22'!AO6+'23'!AO6+'24'!AO6+'25'!AO6+'26'!AO6+'27'!AO6+'28'!AO6+'29'!AO6+'30'!AO6+'31'!AO6 -> 0 | ... W9: =+'1'!AV6+'2'!AV6+'3'!AV6+'4'!AV6+'5'!AV6+'6'!AV6+'7'!AV6+'8'!AV6+'9'!AV6+'10'!AV6+'11'!AV6+'12'!AV6+'13'!AV6+'14'!AV6+'15'!AV6+'16'!AV6+'17'!AV6+'18'!AV6+'19'!AV6+'20'!AV6+'21'!AV6+'22'!AV6+'23'!AV6+'24'!AV6+'25'!AV6+'26'!AV6+'27'!AV6+'28'!AV6+'29'!AV6+'30'!AV6+'31'!AV6 -> 0
C10: H EMBLEM | D10: CN7 PE | E10: =+'1'!AD7+'2'!AD7+'3'!AD7+'4'!AD7+'5'!AD7+'6'!AD7+'7'!AD7+'8'!AD7+'9'!AD7+'10'!AD7+'11'!AD7+'12'!AD7+'13'!AD7+'14'!AD7+'15'!AD7+'16'!AD7+'17'!AD7+'18'!AD7+'19'!AD7+'20'!AD7+'21'!AD7+'22'!AD7+'23'!AD7+'24'!AD7+'25'!AD7+'26'!AD7+'27'!AD7+'28'!AD7+'29'!AD7+'30'!AD7+'31'!AD7 -> 7586 | F10: =+'1'!AE7+'2'!AE7+'3'!AE7+'4'!AE7+'5'!AE7+'6'!AE7+'7'!AE7+'8'!AE7+'9'!AE7+'10'!AE7+'11'!AE7+'12'!AE7+'13'!AE7+'14'!AE7+'15'!AE7+'16'!AE7+'17'!AE7+'18'!AE7+'19'!AE7+'20'!AE7+'21'!AE7+'22'!AE7+'23'!AE7+'24'!AE7+'25'!AE7+'26'!AE7+'27'!AE7+'28'!AE7+'29'!AE7+'30'!AE7+'31'!AE7 -> 7170 | G10: =+'1'!AF7+'2'!AF7+'3'!AF7+'4'!AF7+'5'!AF7+'6'!AF7+'7'!AF7+'8'!AF7+'9'!AF7+'10'!AF7+'11'!AF7+'12'!AF7+'13'!AF7+'14'!AF7+'15'!AF7+'16'!AF7+'17'!AF7+'18'!AF7+'19'!AF7+'20'!AF7+'21'!AF7+'22'!AF7+'23'!AF7+'24'!AF7+'25'!AF7+'26'!AF7+'27'!AF7+'28'!AF7+'29'!AF7+'30'!AF7+'31'!AF7 -> 416 | H10: =IF(E10=0,"",G10/E10) -> 0.054837859 | I10: =+'1'!AH7+'2'!AH7+'3'!AH7+'4'!AH7+'5'!AH7+'6'!AH7+'7'!AH7+'8'!AH7+'9'!AH7+'10'!AH7+'11'!AH7+'12'!AH7+'13'!AH7+'14'!AH7+'15'!AH7+'16'!AH7+'17'!AH7+'18'!AH7+'19'!AH7+'20'!AH7+'21'!AH7+'22'!AH7+'23'!AH7+'24'!AH7+'25'!AH7+'26'!AH7+'27'!AH7+'28'!AH7+'29'!AH7+'30'!AH7+'31'!AH7 -> 1 | J10: =+'1'!AI7+'2'!AI7+'3'!AI7+'4'!AI7+'5'!AI7+'6'!AI7+'7'!AI7+'8'!AI7+'9'!AI7+'10'!AI7+'11'!AI7+'12'!AI7+'13'!AI7+'14'!AI7+'15'!AI7+'16'!AI7+'17'!AI7+'18'!AI7+'19'!AI7+'20'!AI7+'21'!AI7+'22'!AI7+'23'!AI7+'24'!AI7+'25'!AI7+'26'!AI7+'27'!AI7+'28'!AI7+'29'!AI7+'30'!AI7+'31'!AI7 -> 16 | K10: =+'1'!AJ7+'2'!AJ7+'3'!AJ7+'4'!AJ7+'5'!AJ7+'6'!AJ7+'7'!AJ7+'8'!AJ7+'9'!AJ7+'10'!AJ7+'11'!AJ7+'12'!AJ7+'13'!AJ7+'14'!AJ7+'15'!AJ7+'16'!AJ7+'17'!AJ7+'18'!AJ7+'19'!AJ7+'20'!AJ7+'21'!AJ7+'22'!AJ7+'23'!AJ7+'24'!AJ7+'25'!AJ7+'26'!AJ7+'27'!AJ7+'28'!AJ7+'29'!AJ7+'30'!AJ7+'31'!AJ7 -> 0 | L10: =+'1'!AK7+'2'!AK7+'3'!AK7+'4'!AK7+'5'!AK7+'6'!AK7+'7'!AK7+'8'!AK7+'9'!AK7+'10'!AK7+'11'!AK7+'12'!AK7+'13'!AK7+'14'!AK7+'15'!AK7+'16'!AK7+'17'!AK7+'18'!AK7+'19'!AK7+'20'!AK7+'21'!AK7+'22'!AK7+'23'!AK7+'24'!AK7+'25'!AK7+'26'!AK7+'27'!AK7+'28'!AK7+'29'!AK7+'30'!AK7+'31'!AK7 -> 0 | M10: =+'1'!AL7+'2'!AL7+'3'!AL7+'4'!AL7+'5'!AL7+'6'!AL7+'7'!AL7+'8'!AL7+'9'!AL7+'10'!AL7+'11'!AL7+'12'!AL7+'13'!AL7+'14'!AL7+'15'!AL7+'16'!AL7+'17'!AL7+'18'!AL7+'19'!AL7+'20'!AL7+'21'!AL7+'22'!AL7+'23'!AL7+'24'!AL7+'25'!AL7+'26'!AL7+'27'!AL7+'28'!AL7+'29'!AL7+'30'!AL7+'31'!AL7 -> 0 | N10: =+'1'!AM7+'2'!AM7+'3'!AM7+'4'!AM7+'5'!AM7+'6'!AM7+'7'!AM7+'8'!AM7+'9'!AM7+'10'!AM7+'11'!AM7+'12'!AM7+'13'!AM7+'14'!AM7+'15'!AM7+'16'!AM7+'17'!AM7+'18'!AM7+'19'!AM7+'20'!AM7+'21'!AM7+'22'!AM7+'23'!AM7+'24'!AM7+'25'!AM7+'26'!AM7+'27'!AM7+'28'!AM7+'29'!AM7+'30'!AM7+'31'!AM7 -> 0 | O10: =+'1'!AN7+'2'!AN7+'3'!AN7+'4'!AN7+'5'!AN7+'6'!AN7+'7'!AN7+'8'!AN7+'9'!AN7+'10'!AN7+'11'!AN7+'12'!AN7+'13'!AN7+'14'!AN7+'15'!AN7+'16'!AN7+'17'!AN7+'18'!AN7+'19'!AN7+'20'!AN7+'21'!AN7+'22'!AN7+'23'!AN7+'24'!AN7+'25'!AN7+'26'!AN7+'27'!AN7+'28'!AN7+'29'!AN7+'30'!AN7+'31'!AN7 -> 109 | P10: =+'1'!AO7+'2'!AO7+'3'!AO7+'4'!AO7+'5'!AO7+'6'!AO7+'7'!AO7+'8'!AO7+'9'!AO7+'10'!AO7+'11'!AO7+'12'!AO7+'13'!AO7+'14'!AO7+'15'!AO7+'16'!AO7+'17'!AO7+'18'!AO7+'19'!AO7+'20'!AO7+'21'!AO7+'22'!AO7+'23'!AO7+'24'!AO7+'25'!AO7+'26'!AO7+'27'!AO7+'28'!AO7+'29'!AO7+'30'!AO7+'31'!AO7 -> 5 | ... W10: =+'1'!AV7+'2'!AV7+'3'!AV7+'4'!AV7+'5'!AV7+'6'!AV7+'7'!AV7+'8'!AV7+'9'!AV7+'10'!AV7+'11'!AV7+'12'!AV7+'13'!AV7+'14'!AV7+'15'!AV7+'16'!AV7+'17'!AV7+'18'!AV7+'19'!AV7+'20'!AV7+'21'!AV7+'22'!AV7+'23'!AV7+'24'!AV7+'25'!AV7+'26'!AV7+'27'!AV7+'28'!AV7+'29'!AV7+'30'!AV7+'31'!AV7 -> 0
C11: GN7 BEZEL | D11: GN7 | E11: =+'1'!AD8+'2'!AD8+'3'!AD8+'4'!AD8+'5'!AD8+'6'!AD8+'7'!AD8+'8'!AD8+'9'!AD8+'10'!AD8+'11'!AD8+'12'!AD8+'13'!AD8+'14'!AD8+'15'!AD8+'16'!AD8+'17'!AD8+'18'!AD8+'19'!AD8+'20'!AD8+'21'!AD8+'22'!AD8+'23'!AD8+'24'!AD8+'25'!AD8+'26'!AD8+'27'!AD8+'28'!AD8+'29'!AD8+'30'!AD8+'31'!AD8 -> 0 | F11: =+'1'!AE8+'2'!AE8+'3'!AE8+'4'!AE8+'5'!AE8+'6'!AE8+'7'!AE8+'8'!AE8+'9'!AE8+'10'!AE8+'11'!AE8+'12'!AE8+'13'!AE8+'14'!AE8+'15'!AE8+'16'!AE8+'17'!AE8+'18'!AE8+'19'!AE8+'20'!AE8+'21'!AE8+'22'!AE8+'23'!AE8+'24'!AE8+'25'!AE8+'26'!AE8+'27'!AE8+'28'!AE8+'29'!AE8+'30'!AE8+'31'!AE8 -> 0 | G11: =+'1'!AF8+'2'!AF8+'3'!AF8+'4'!AF8+'5'!AF8+'6'!AF8+'7'!AF8+'8'!AF8+'9'!AF8+'10'!AF8+'11'!AF8+'12'!AF8+'13'!AF8+'14'!AF8+'15'!AF8+'16'!AF8+'17'!AF8+'18'!AF8+'19'!AF8+'20'!AF8+'21'!AF8+'22'!AF8+'23'!AF8+'24'!AF8+'25'!AF8+'26'!AF8+'27'!AF8+'28'!AF8+'29'!AF8+'30'!AF8+'31'!AF8 -> 0 | H11: =IF(E11=0,"",G11/E11) | I11: =+'1'!AH8+'2'!AH8+'3'!AH8+'4'!AH8+'5'!AH8+'6'!AH8+'7'!AH8+'8'!AH8+'9'!AH8+'10'!AH8+'11'!AH8+'12'!AH8+'13'!AH8+'14'!AH8+'15'!AH8+'16'!AH8+'17'!AH8+'18'!AH8+'19'!AH8+'20'!AH8+'21'!AH8+'22'!AH8+'23'!AH8+'24'!AH8+'25'!AH8+'26'!AH8+'27'!AH8+'28'!AH8+'29'!AH8+'30'!AH8+'31'!AH8 -> 0 | J11: =+'1'!AI8+'2'!AI8+'3'!AI8+'4'!AI8+'5'!AI8+'6'!AI8+'7'!AI8+'8'!AI8+'9'!AI8+'10'!AI8+'11'!AI8+'12'!AI8+'13'!AI8+'14'!AI8+'15'!AI8+'16'!AI8+'17'!AI8+'18'!AI8+'19'!AI8+'20'!AI8+'21'!AI8+'22'!AI8+'23'!AI8+'24'!AI8+'25'!AI8+'26'!AI8+'27'!AI8+'28'!AI8+'29'!AI8+'30'!AI8+'31'!AI8 -> 0 | K11: =+'1'!AJ8+'2'!AJ8+'3'!AJ8+'4'!AJ8+'5'!AJ8+'6'!AJ8+'7'!AJ8+'8'!AJ8+'9'!AJ8+'10'!AJ8+'11'!AJ8+'12'!AJ8+'13'!AJ8+'14'!AJ8+'15'!AJ8+'16'!AJ8+'17'!AJ8+'18'!AJ8+'19'!AJ8+'20'!AJ8+'21'!AJ8+'22'!AJ8+'23'!AJ8+'24'!AJ8+'25'!AJ8+'26'!AJ8+'27'!AJ8+'28'!AJ8+'29'!AJ8+'30'!AJ8+'31'!AJ8 -> 0 | L11: =+'1'!AK8+'2'!AK8+'3'!AK8+'4'!AK8+'5'!AK8+'6'!AK8+'7'!AK8+'8'!AK8+'9'!AK8+'10'!AK8+'11'!AK8+'12'!AK8+'13'!AK8+'14'!AK8+'15'!AK8+'16'!AK8+'17'!AK8+'18'!AK8+'19'!AK8+'20'!AK8+'21'!AK8+'22'!AK8+'23'!AK8+'24'!AK8+'25'!AK8+'26'!AK8+'27'!AK8+'28'!AK8+'29'!AK8+'30'!AK8+'31'!AK8 -> 0 | M11: =+'1'!AL8+'2'!AL8+'3'!AL8+'4'!AL8+'5'!AL8+'6'!AL8+'7'!AL8+'8'!AL8+'9'!AL8+'10'!AL8+'11'!AL8+'12'!AL8+'13'!AL8+'14'!AL8+'15'!AL8+'16'!AL8+'17'!AL8+'18'!AL8+'19'!AL8+'20'!AL8+'21'!AL8+'22'!AL8+'23'!AL8+'24'!AL8+'25'!AL8+'26'!AL8+'27'!AL8+'28'!AL8+'29'!AL8+'30'!AL8+'31'!AL8 -> 0 | N11: =+'1'!AM8+'2'!AM8+'3'!AM8+'4'!AM8+'5'!AM8+'6'!AM8+'7'!AM8+'8'!AM8+'9'!AM8+'10'!AM8+'11'!AM8+'12'!AM8+'13'!AM8+'14'!AM8+'15'!AM8+'16'!AM8+'17'!AM8+'18'!AM8+'19'!AM8+'20'!AM8+'21'!AM8+'22'!AM8+'23'!AM8+'24'!AM8+'25'!AM8+'26'!AM8+'27'!AM8+'28'!AM8+'29'!AM8+'30'!AM8+'31'!AM8 -> 0 | O11: =+'1'!AN8+'2'!AN8+'3'!AN8+'4'!AN8+'5'!AN8+'6'!AN8+'7'!AN8+'8'!AN8+'9'!AN8+'10'!AN8+'11'!AN8+'12'!AN8+'13'!AN8+'14'!AN8+'15'!AN8+'16'!AN8+'17'!AN8+'18'!AN8+'19'!AN8+'20'!AN8+'21'!AN8+'22'!AN8+'23'!AN8+'24'!AN8+'25'!AN8+'26'!AN8+'27'!AN8+'28'!AN8+'29'!AN8+'30'!AN8+'31'!AN8 -> 0 | P11: =+'1'!AO8+'2'!AO8+'3'!AO8+'4'!AO8+'5'!AO8+'6'!AO8+'7'!AO8+'8'!AO8+'9'!AO8+'10'!AO8+'11'!AO8+'12'!AO8+'13'!AO8+'14'!AO8+'15'!AO8+'16'!AO8+'17'!AO8+'18'!AO8+'19'!AO8+'20'!AO8+'21'!AO8+'22'!AO8+'23'!AO8+'24'!AO8+'25'!AO8+'26'!AO8+'27'!AO8+'28'!AO8+'29'!AO8+'30'!AO8+'31'!AO8 -> 0 | ... W11: =+'1'!AV8+'2'!AV8+'3'!AV8+'4'!AV8+'5'!AV8+'6'!AV8+'7'!AV8+'8'!AV8+'9'!AV8+'10'!AV8+'11'!AV8+'12'!AV8+'13'!AV8+'14'!AV8+'15'!AV8+'16'!AV8+'17'!AV8+'18'!AV8+'19'!AV8+'20'!AV8+'21'!AV8+'22'!AV8+'23'!AV8+'24'!AV8+'25'!AV8+'26'!AV8+'27'!AV8+'28'!AV8+'29'!AV8+'30'!AV8+'31'!AV8 -> 0
C12: 45MM | D12: CL4 | E12: =+'1'!AD9+'2'!AD9+'3'!AD9+'4'!AD9+'5'!AD9+'6'!AD9+'7'!AD9+'8'!AD9+'9'!AD9+'10'!AD9+'11'!AD9+'12'!AD9+'13'!AD9+'14'!AD9+'15'!AD9+'16'!AD9+'17'!AD9+'18'!AD9+'19'!AD9+'20'!AD9+'21'!AD9+'22'!AD9+'23'!AD9+'24'!AD9+'25'!AD9+'26'!AD9+'27'!AD9+'28'!AD9+'29'!AD9+'30'!AD9+'31'!AD9 -> 0 | F12: =+'1'!AE9+'2'!AE9+'3'!AE9+'4'!AE9+'5'!AE9+'6'!AE9+'7'!AE9+'8'!AE9+'9'!AE9+'10'!AE9+'11'!AE9+'12'!AE9+'13'!AE9+'14'!AE9+'15'!AE9+'16'!AE9+'17'!AE9+'18'!AE9+'19'!AE9+'20'!AE9+'21'!AE9+'22'!AE9+'23'!AE9+'24'!AE9+'25'!AE9+'26'!AE9+'27'!AE9+'28'!AE9+'29'!AE9+'30'!AE9+'31'!AE9 -> 0 | G12: =+'1'!AF9+'2'!AF9+'3'!AF9+'4'!AF9+'5'!AF9+'6'!AF9+'7'!AF9+'8'!AF9+'9'!AF9+'10'!AF9+'11'!AF9+'12'!AF9+'13'!AF9+'14'!AF9+'15'!AF9+'16'!AF9+'17'!AF9+'18'!AF9+'19'!AF9+'20'!AF9+'21'!AF9+'22'!AF9+'23'!AF9+'24'!AF9+'25'!AF9+'26'!AF9+'27'!AF9+'28'!AF9+'29'!AF9+'30'!AF9+'31'!AF9 -> 0 | H12: =IF(E12=0,"",G12/E12) | I12: =+'1'!AH9+'2'!AH9+'3'!AH9+'4'!AH9+'5'!AH9+'6'!AH9+'7'!AH9+'8'!AH9+'9'!AH9+'10'!AH9+'11'!AH9+'12'!AH9+'13'!AH9+'14'!AH9+'15'!AH9+'16'!AH9+'17'!AH9+'18'!AH9+'19'!AH9+'20'!AH9+'21'!AH9+'22'!AH9+'23'!AH9+'24'!AH9+'25'!AH9+'26'!AH9+'27'!AH9+'28'!AH9+'29'!AH9+'30'!AH9+'31'!AH9 -> 0 | J12: =+'1'!AI9+'2'!AI9+'3'!AI9+'4'!AI9+'5'!AI9+'6'!AI9+'7'!AI9+'8'!AI9+'9'!AI9+'10'!AI9+'11'!AI9+'12'!AI9+'13'!AI9+'14'!AI9+'15'!AI9+'16'!AI9+'17'!AI9+'18'!AI9+'19'!AI9+'20'!AI9+'21'!AI9+'22'!AI9+'23'!AI9+'24'!AI9+'25'!AI9+'26'!AI9+'27'!AI9+'28'!AI9+'29'!AI9+'30'!AI9+'31'!AI9 -> 0 | K12: =+'1'!AJ9+'2'!AJ9+'3'!AJ9+'4'!AJ9+'5'!AJ9+'6'!AJ9+'7'!AJ9+'8'!AJ9+'9'!AJ9+'10'!AJ9+'11'!AJ9+'12'!AJ9+'13'!AJ9+'14'!AJ9+'15'!AJ9+'16'!AJ9+'17'!AJ9+'18'!AJ9+'19'!AJ9+'20'!AJ9+'21'!AJ9+'22'!AJ9+'23'!AJ9+'24'!AJ9+'25'!AJ9+'26'!AJ9+'27'!AJ9+'28'!AJ9+'29'!AJ9+'30'!AJ9+'31'!AJ9 -> 0 | L12: =+'1'!AK9+'2'!AK9+'3'!AK9+'4'!AK9+'5'!AK9+'6'!AK9+'7'!AK9+'8'!AK9+'9'!AK9+'10'!AK9+'11'!AK9+'12'!AK9+'13'!AK9+'14'!AK9+'15'!AK9+'16'!AK9+'17'!AK9+'18'!AK9+'19'!AK9+'20'!AK9+'21'!AK9+'22'!AK9+'23'!AK9+'24'!AK9+'25'!AK9+'26'!AK9+'27'!AK9+'28'!AK9+'29'!AK9+'30'!AK9+'31'!AK9 -> 0 | M12: =+'1'!AL9+'2'!AL9+'3'!AL9+'4'!AL9+'5'!AL9+'6'!AL9+'7'!AL9+'8'!AL9+'9'!AL9+'10'!AL9+'11'!AL9+'12'!AL9+'13'!AL9+'14'!AL9+'15'!AL9+'16'!AL9+'17'!AL9+'18'!AL9+'19'!AL9+'20'!AL9+'21'!AL9+'22'!AL9+'23'!AL9+'24'!AL9+'25'!AL9+'26'!AL9+'27'!AL9+'28'!AL9+'29'!AL9+'30'!AL9+'31'!AL9 -> 0 | N12: =+'1'!AM9+'2'!AM9+'3'!AM9+'4'!AM9+'5'!AM9+'6'!AM9+'7'!AM9+'8'!AM9+'9'!AM9+'10'!AM9+'11'!AM9+'12'!AM9+'13'!AM9+'14'!AM9+'15'!AM9+'16'!AM9+'17'!AM9+'18'!AM9+'19'!AM9+'20'!AM9+'21'!AM9+'22'!AM9+'23'!AM9+'24'!AM9+'25'!AM9+'26'!AM9+'27'!AM9+'28'!AM9+'29'!AM9+'30'!AM9+'31'!AM9 -> 0 | O12: =+'1'!AN9+'2'!AN9+'3'!AN9+'4'!AN9+'5'!AN9+'6'!AN9+'7'!AN9+'8'!AN9+'9'!AN9+'10'!AN9+'11'!AN9+'12'!AN9+'13'!AN9+'14'!AN9+'15'!AN9+'16'!AN9+'17'!AN9+'18'!AN9+'19'!AN9+'20'!AN9+'21'!AN9+'22'!AN9+'23'!AN9+'24'!AN9+'25'!AN9+'26'!AN9+'27'!AN9+'28'!AN9+'29'!AN9+'30'!AN9+'31'!AN9 -> 0 | P12: =+'1'!AO9+'2'!AO9+'3'!AO9+'4'!AO9+'5'!AO9+'6'!AO9+'7'!AO9+'8'!AO9+'9'!AO9+'10'!AO9+'11'!AO9+'12'!AO9+'13'!AO9+'14'!AO9+'15'!AO9+'16'!AO9+'17'!AO9+'18'!AO9+'19'!AO9+'20'!AO9+'21'!AO9+'22'!AO9+'23'!AO9+'24'!AO9+'25'!AO9+'26'!AO9+'27'!AO9+'28'!AO9+'29'!AO9+'30'!AO9+'31'!AO9 -> 0 | ... W12: =+'1'!AV9+'2'!AV9+'3'!AV9+'4'!AV9+'5'!AV9+'6'!AV9+'7'!AV9+'8'!AV9+'9'!AV9+'10'!AV9+'11'!AV9+'12'!AV9+'13'!AV9+'14'!AV9+'15'!AV9+'16'!AV9+'17'!AV9+'18'!AV9+'19'!AV9+'20'!AV9+'21'!AV9+'22'!AV9+'23'!AV9+'24'!AV9+'25'!AV9+'26'!AV9+'27'!AV9+'28'!AV9+'29'!AV9+'30'!AV9+'31'!AV9 -> 0
C13: 제네시스 | D13: JW1 PE | E13: =+'1'!AD10+'2'!AD10+'3'!AD10+'4'!AD10+'5'!AD10+'6'!AD10+'7'!AD10+'8'!AD10+'9'!AD10+'10'!AD10+'11'!AD10+'12'!AD10+'13'!AD10+'14'!AD10+'15'!AD10+'16'!AD10+'17'!AD10+'18'!AD10+'19'!AD10+'20'!AD10+'21'!AD10+'22'!AD10+'23'!AD10+'24'!AD10+'25'!AD10+'26'!AD10+'27'!AD10+'28'!AD10+'29'!AD10+'30'!AD10+'31'!AD10 -> 0 | F13: =+'1'!AE10+'2'!AE10+'3'!AE10+'4'!AE10+'5'!AE10+'6'!AE10+'7'!AE10+'8'!AE10+'9'!AE10+'10'!AE10+'11'!AE10+'12'!AE10+'13'!AE10+'14'!AE10+'15'!AE10+'16'!AE10+'17'!AE10+'18'!AE10+'19'!AE10+'20'!AE10+'21'!AE10+'22'!AE10+'23'!AE10+'24'!AE10+'25'!AE10+'26'!AE10+'27'!AE10+'28'!AE10+'29'!AE10+'30'!AE10+'31'!AE10 -> 0 | G13: =+'1'!AF10+'2'!AF10+'3'!AF10+'4'!AF10+'5'!AF10+'6'!AF10+'7'!AF10+'8'!AF10+'9'!AF10+'10'!AF10+'11'!AF10+'12'!AF10+'13'!AF10+'14'!AF10+'15'!AF10+'16'!AF10+'17'!AF10+'18'!AF10+'19'!AF10+'20'!AF10+'21'!AF10+'22'!AF10+'23'!AF10+'24'!AF10+'25'!AF10+'26'!AF10+'27'!AF10+'28'!AF10+'29'!AF10+'30'!AF10+'31'!AF10 -> 0 | H13: =IF(E13=0,"",G13/E13) | I13: =+'1'!AH10+'2'!AH10+'3'!AH10+'4'!AH10+'5'!AH10+'6'!AH10+'7'!AH10+'8'!AH10+'9'!AH10+'10'!AH10+'11'!AH10+'12'!AH10+'13'!AH10+'14'!AH10+'15'!AH10+'16'!AH10+'17'!AH10+'18'!AH10+'19'!AH10+'20'!AH10+'21'!AH10+'22'!AH10+'23'!AH10+'24'!AH10+'25'!AH10+'26'!AH10+'27'!AH10+'28'!AH10+'29'!AH10+'30'!AH10+'31'!AH10 -> 0 | J13: =+'1'!AI10+'2'!AI10+'3'!AI10+'4'!AI10+'5'!AI10+'6'!AI10+'7'!AI10+'8'!AI10+'9'!AI10+'10'!AI10+'11'!AI10+'12'!AI10+'13'!AI10+'14'!AI10+'15'!AI10+'16'!AI10+'17'!AI10+'18'!AI10+'19'!AI10+'20'!AI10+'21'!AI10+'22'!AI10+'23'!AI10+'24'!AI10+'25'!AI10+'26'!AI10+'27'!AI10+'28'!AI10+'29'!AI10+'30'!AI10+'31'!AI10 -> 0 | K13: =+'1'!AJ10+'2'!AJ10+'3'!AJ10+'4'!AJ10+'5'!AJ10+'6'!AJ10+'7'!AJ10+'8'!AJ10+'9'!AJ10+'10'!AJ10+'11'!AJ10+'12'!AJ10+'13'!AJ10+'14'!AJ10+'15'!AJ10+'16'!AJ10+'17'!AJ10+'18'!AJ10+'19'!AJ10+'20'!AJ10+'21'!AJ10+'22'!AJ10+'23'!AJ10+'24'!AJ10+'25'!AJ10+'26'!AJ10+'27'!AJ10+'28'!AJ10+'29'!AJ10+'30'!AJ10+'31'!AJ10 -> 0 | L13: =+'1'!AK10+'2'!AK10+'3'!AK10+'4'!AK10+'5'!AK10+'6'!AK10+'7'!AK10+'8'!AK10+'9'!AK10+'10'!AK10+'11'!AK10+'12'!AK10+'13'!AK10+'14'!AK10+'15'!AK10+'16'!AK10+'17'!AK10+'18'!AK10+'19'!AK10+'20'!AK10+'21'!AK10+'22'!AK10+'23'!AK10+'24'!AK10+'25'!AK10+'26'!AK10+'27'!AK10+'28'!AK10+'29'!AK10+'30'!AK10+'31'!AK10 -> 0 | M13: =+'1'!AL10+'2'!AL10+'3'!AL10+'4'!AL10+'5'!AL10+'6'!AL10+'7'!AL10+'8'!AL10+'9'!AL10+'10'!AL10+'11'!AL10+'12'!AL10+'13'!AL10+'14'!AL10+'15'!AL10+'16'!AL10+'17'!AL10+'18'!AL10+'19'!AL10+'20'!AL10+'21'!AL10+'22'!AL10+'23'!AL10+'24'!AL10+'25'!AL10+'26'!AL10+'27'!AL10+'28'!AL10+'29'!AL10+'30'!AL10+'31'!AL10 -> 0 | N13: =+'1'!AM10+'2'!AM10+'3'!AM10+'4'!AM10+'5'!AM10+'6'!AM10+'7'!AM10+'8'!AM10+'9'!AM10+'10'!AM10+'11'!AM10+'12'!AM10+'13'!AM10+'14'!AM10+'15'!AM10+'16'!AM10+'17'!AM10+'18'!AM10+'19'!AM10+'20'!AM10+'21'!AM10+'22'!AM10+'23'!AM10+'24'!AM10+'25'!AM10+'26'!AM10+'27'!AM10+'28'!AM10+'29'!AM10+'30'!AM10+'31'!AM10 -> 0 | O13: =+'1'!AN10+'2'!AN10+'3'!AN10+'4'!AN10+'5'!AN10+'6'!AN10+'7'!AN10+'8'!AN10+'9'!AN10+'10'!AN10+'11'!AN10+'12'!AN10+'13'!AN10+'14'!AN10+'15'!AN10+'16'!AN10+'17'!AN10+'18'!AN10+'19'!AN10+'20'!AN10+'21'!AN10+'22'!AN10+'23'!AN10+'24'!AN10+'25'!AN10+'26'!AN10+'27'!AN10+'28'!AN10+'29'!AN10+'30'!AN10+'31'!AN10 -> 0 | P13: =+'1'!AO10+'2'!AO10+'3'!AO10+'4'!AO10+'5'!AO10+'6'!AO10+'7'!AO10+'8'!AO10+'9'!AO10+'10'!AO10+'11'!AO10+'12'!AO10+'13'!AO10+'14'!AO10+'15'!AO10+'16'!AO10+'17'!AO10+'18'!AO10+'19'!AO10+'20'!AO10+'21'!AO10+'22'!AO10+'23'!AO10+'24'!AO10+'25'!AO10+'26'!AO10+'27'!AO10+'28'!AO10+'29'!AO10+'30'!AO10+'31'!AO10 -> 0 | ... W13: =+'1'!AV10+'2'!AV10+'3'!AV10+'4'!AV10+'5'!AV10+'6'!AV10+'7'!AV10+'8'!AV10+'9'!AV10+'10'!AV10+'11'!AV10+'12'!AV10+'13'!AV10+'14'!AV10+'15'!AV10+'16'!AV10+'17'!AV10+'18'!AV10+'19'!AV10+'20'!AV10+'21'!AV10+'22'!AV10+'23'!AV10+'24'!AV10+'25'!AV10+'26'!AV10+'27'!AV10+'28'!AV10+'29'!AV10+'30'!AV10+'31'!AV10 -> 0
C14: B | D14: 나 | E14: =+'1'!AD11+'2'!AD11+'3'!AD11+'4'!AD11+'5'!AD11+'6'!AD11+'7'!AD11+'8'!AD11+'9'!AD11+'10'!AD11+'11'!AD11+'12'!AD11+'13'!AD11+'14'!AD11+'15'!AD11+'16'!AD11+'17'!AD11+'18'!AD11+'19'!AD11+'20'!AD11+'21'!AD11+'22'!AD11+'23'!AD11+'24'!AD11+'25'!AD11+'26'!AD11+'27'!AD11+'28'!AD11+'29'!AD11+'30'!AD11+'31'!AD11 -> 1872 | F14: =+'1'!AE11+'2'!AE11+'3'!AE11+'4'!AE11+'5'!AE11+'6'!AE11+'7'!AE11+'8'!AE11+'9'!AE11+'10'!AE11+'11'!AE11+'12'!AE11+'13'!AE11+'14'!AE11+'15'!AE11+'16'!AE11+'17'!AE11+'18'!AE11+'19'!AE11+'20'!AE11+'21'!AE11+'22'!AE11+'23'!AE11+'24'!AE11+'25'!AE11+'26'!AE11+'27'!AE11+'28'!AE11+'29'!AE11+'30'!AE11+'31'!AE11 -> 1837 | G14: =+'1'!AF11+'2'!AF11+'3'!AF11+'4'!AF11+'5'!AF11+'6'!AF11+'7'!AF11+'8'!AF11+'9'!AF11+'10'!AF11+'11'!AF11+'12'!AF11+'13'!AF11+'14'!AF11+'15'!AF11+'16'!AF11+'17'!AF11+'18'!AF11+'19'!AF11+'20'!AF11+'21'!AF11+'22'!AF11+'23'!AF11+'24'!AF11+'25'!AF11+'26'!AF11+'27'!AF11+'28'!AF11+'29'!AF11+'30'!AF11+'31'!AF11 -> 35 | H14: =IF(E14=0,"",G14/E14) -> 0.018696581 | I14: =+'1'!AH11+'2'!AH11+'3'!AH11+'4'!AH11+'5'!AH11+'6'!AH11+'7'!AH11+'8'!AH11+'9'!AH11+'10'!AH11+'11'!AH11+'12'!AH11+'13'!AH11+'14'!AH11+'15'!AH11+'16'!AH11+'17'!AH11+'18'!AH11+'19'!AH11+'20'!AH11+'21'!AH11+'22'!AH11+'23'!AH11+'24'!AH11+'25'!AH11+'26'!AH11+'27'!AH11+'28'!AH11+'29'!AH11+'30'!AH11+'31'!AH11 -> 0 | J14: =+'1'!AI11+'2'!AI11+'3'!AI11+'4'!AI11+'5'!AI11+'6'!AI11+'7'!AI11+'8'!AI11+'9'!AI11+'10'!AI11+'11'!AI11+'12'!AI11+'13'!AI11+'14'!AI11+'15'!AI11+'16'!AI11+'17'!AI11+'18'!AI11+'19'!AI11+'20'!AI11+'21'!AI11+'22'!AI11+'23'!AI11+'24'!AI11+'25'!AI11+'26'!AI11+'27'!AI11+'28'!AI11+'29'!AI11+'30'!AI11+'31'!AI11 -> 10 | K14: =+'1'!AJ11+'2'!AJ11+'3'!AJ11+'4'!AJ11+'5'!AJ11+'6'!AJ11+'7'!AJ11+'8'!AJ11+'9'!AJ11+'10'!AJ11+'11'!AJ11+'12'!AJ11+'13'!AJ11+'14'!AJ11+'15'!AJ11+'16'!AJ11+'17'!AJ11+'18'!AJ11+'19'!AJ11+'20'!AJ11+'21'!AJ11+'22'!AJ11+'23'!AJ11+'24'!AJ11+'25'!AJ11+'26'!AJ11+'27'!AJ11+'28'!AJ11+'29'!AJ11+'30'!AJ11+'31'!AJ11 -> 6 | L14: =+'1'!AK11+'2'!AK11+'3'!AK11+'4'!AK11+'5'!AK11+'6'!AK11+'7'!AK11+'8'!AK11+'9'!AK11+'10'!AK11+'11'!AK11+'12'!AK11+'13'!AK11+'14'!AK11+'15'!AK11+'16'!AK11+'17'!AK11+'18'!AK11+'19'!AK11+'20'!AK11+'21'!AK11+'22'!AK11+'23'!AK11+'24'!AK11+'25'!AK11+'26'!AK11+'27'!AK11+'28'!AK11+'29'!AK11+'30'!AK11+'31'!AK11 -> 3 | M14: =+'1'!AL11+'2'!AL11+'3'!AL11+'4'!AL11+'5'!AL11+'6'!AL11+'7'!AL11+'8'!AL11+'9'!AL11+'10'!AL11+'11'!AL11+'12'!AL11+'13'!AL11+'14'!AL11+'15'!AL11+'16'!AL11+'17'!AL11+'18'!AL11+'19'!AL11+'20'!AL11+'21'!AL11+'22'!AL11+'23'!AL11+'24'!AL11+'25'!AL11+'26'!AL11+'27'!AL11+'28'!AL11+'29'!AL11+'30'!AL11+'31'!AL11 -> 0 | N14: =+'1'!AM11+'2'!AM11+'3'!AM11+'4'!AM11+'5'!AM11+'6'!AM11+'7'!AM11+'8'!AM11+'9'!AM11+'10'!AM11+'11'!AM11+'12'!AM11+'13'!AM11+'14'!AM11+'15'!AM11+'16'!AM11+'17'!AM11+'18'!AM11+'19'!AM11+'20'!AM11+'21'!AM11+'22'!AM11+'23'!AM11+'24'!AM11+'25'!AM11+'26'!AM11+'27'!AM11+'28'!AM11+'29'!AM11+'30'!AM11+'31'!AM11 -> 0 | O14: =+'1'!AN11+'2'!AN11+'3'!AN11+'4'!AN11+'5'!AN11+'6'!AN11+'7'!AN11+'8'!AN11+'9'!AN11+'10'!AN11+'11'!AN11+'12'!AN11+'13'!AN11+'14'!AN11+'15'!AN11+'16'!AN11+'17'!AN11+'18'!AN11+'19'!AN11+'20'!AN11+'21'!AN11+'22'!AN11+'23'!AN11+'24'!AN11+'25'!AN11+'26'!AN11+'27'!AN11+'28'!AN11+'29'!AN11+'30'!AN11+'31'!AN11 -> 16 | P14: =+'1'!AO11+'2'!AO11+'3'!AO11+'4'!AO11+'5'!AO11+'6'!AO11+'7'!AO11+'8'!AO11+'9'!AO11+'10'!AO11+'11'!AO11+'12'!AO11+'13'!AO11+'14'!AO11+'15'!AO11+'16'!AO11+'17'!AO11+'18'!AO11+'19'!AO11+'20'!AO11+'21'!AO11+'22'!AO11+'23'!AO11+'24'!AO11+'25'!AO11+'26'!AO11+'27'!AO11+'28'!AO11+'29'!AO11+'30'!AO11+'31'!AO11 -> 0 | ... W14: =+'1'!AV11+'2'!AV11+'3'!AV11+'4'!AV11+'5'!AV11+'6'!AV11+'7'!AV11+'8'!AV11+'9'!AV11+'10'!AV11+'11'!AV11+'12'!AV11+'13'!AV11+'14'!AV11+'15'!AV11+'16'!AV11+'17'!AV11+'18'!AV11+'19'!AV11+'20'!AV11+'21'!AV11+'22'!AV11+'23'!AV11+'24'!AV11+'25'!AV11+'26'!AV11+'27'!AV11+'28'!AV11+'29'!AV11+'30'!AV11+'31'!AV11 -> 0
C15: MX5 BEZEL | D15: MX5 | E15: =+'1'!AD12+'2'!AD12+'3'!AD12+'4'!AD12+'5'!AD12+'6'!AD12+'7'!AD12+'8'!AD12+'9'!AD12+'10'!AD12+'11'!AD12+'12'!AD12+'13'!AD12+'14'!AD12+'15'!AD12+'16'!AD12+'17'!AD12+'18'!AD12+'19'!AD12+'20'!AD12+'21'!AD12+'22'!AD12+'23'!AD12+'24'!AD12+'25'!AD12+'26'!AD12+'27'!AD12+'28'!AD12+'29'!AD12+'30'!AD12+'31'!AD12 -> 0 | F15: =+'1'!AE12+'2'!AE12+'3'!AE12+'4'!AE12+'5'!AE12+'6'!AE12+'7'!AE12+'8'!AE12+'9'!AE12+'10'!AE12+'11'!AE12+'12'!AE12+'13'!AE12+'14'!AE12+'15'!AE12+'16'!AE12+'17'!AE12+'18'!AE12+'19'!AE12+'20'!AE12+'21'!AE12+'22'!AE12+'23'!AE12+'24'!AE12+'25'!AE12+'26'!AE12+'27'!AE12+'28'!AE12+'29'!AE12+'30'!AE12+'31'!AE12 -> 0 | G15: =+'1'!AF12+'2'!AF12+'3'!AF12+'4'!AF12+'5'!AF12+'6'!AF12+'7'!AF12+'8'!AF12+'9'!AF12+'10'!AF12+'11'!AF12+'12'!AF12+'13'!AF12+'14'!AF12+'15'!AF12+'16'!AF12+'17'!AF12+'18'!AF12+'19'!AF12+'20'!AF12+'21'!AF12+'22'!AF12+'23'!AF12+'24'!AF12+'25'!AF12+'26'!AF12+'27'!AF12+'28'!AF12+'29'!AF12+'30'!AF12+'31'!AF12 -> 0 | H15: =IF(E15=0,"",G15/E15) | I15: =+'1'!AH12+'2'!AH12+'3'!AH12+'4'!AH12+'5'!AH12+'6'!AH12+'7'!AH12+'8'!AH12+'9'!AH12+'10'!AH12+'11'!AH12+'12'!AH12+'13'!AH12+'14'!AH12+'15'!AH12+'16'!AH12+'17'!AH12+'18'!AH12+'19'!AH12+'20'!AH12+'21'!AH12+'22'!AH12+'23'!AH12+'24'!AH12+'25'!AH12+'26'!AH12+'27'!AH12+'28'!AH12+'29'!AH12+'30'!AH12+'31'!AH12 -> 0 | J15: =+'1'!AI12+'2'!AI12+'3'!AI12+'4'!AI12+'5'!AI12+'6'!AI12+'7'!AI12+'8'!AI12+'9'!AI12+'10'!AI12+'11'!AI12+'12'!AI12+'13'!AI12+'14'!AI12+'15'!AI12+'16'!AI12+'17'!AI12+'18'!AI12+'19'!AI12+'20'!AI12+'21'!AI12+'22'!AI12+'23'!AI12+'24'!AI12+'25'!AI12+'26'!AI12+'27'!AI12+'28'!AI12+'29'!AI12+'30'!AI12+'31'!AI12 -> 0 | K15: =+'1'!AJ12+'2'!AJ12+'3'!AJ12+'4'!AJ12+'5'!AJ12+'6'!AJ12+'7'!AJ12+'8'!AJ12+'9'!AJ12+'10'!AJ12+'11'!AJ12+'12'!AJ12+'13'!AJ12+'14'!AJ12+'15'!AJ12+'16'!AJ12+'17'!AJ12+'18'!AJ12+'19'!AJ12+'20'!AJ12+'21'!AJ12+'22'!AJ12+'23'!AJ12+'24'!AJ12+'25'!AJ12+'26'!AJ12+'27'!AJ12+'28'!AJ12+'29'!AJ12+'30'!AJ12+'31'!AJ12 -> 0 | L15: =+'1'!AK12+'2'!AK12+'3'!AK12+'4'!AK12+'5'!AK12+'6'!AK12+'7'!AK12+'8'!AK12+'9'!AK12+'10'!AK12+'11'!AK12+'12'!AK12+'13'!AK12+'14'!AK12+'15'!AK12+'16'!AK12+'17'!AK12+'18'!AK12+'19'!AK12+'20'!AK12+'21'!AK12+'22'!AK12+'23'!AK12+'24'!AK12+'25'!AK12+'26'!AK12+'27'!AK12+'28'!AK12+'29'!AK12+'30'!AK12+'31'!AK12 -> 0 | M15: =+'1'!AL12+'2'!AL12+'3'!AL12+'4'!AL12+'5'!AL12+'6'!AL12+'7'!AL12+'8'!AL12+'9'!AL12+'10'!AL12+'11'!AL12+'12'!AL12+'13'!AL12+'14'!AL12+'15'!AL12+'16'!AL12+'17'!AL12+'18'!AL12+'19'!AL12+'20'!AL12+'21'!AL12+'22'!AL12+'23'!AL12+'24'!AL12+'25'!AL12+'26'!AL12+'27'!AL12+'28'!AL12+'29'!AL12+'30'!AL12+'31'!AL12 -> 0 | N15: =+'1'!AM12+'2'!AM12+'3'!AM12+'4'!AM12+'5'!AM12+'6'!AM12+'7'!AM12+'8'!AM12+'9'!AM12+'10'!AM12+'11'!AM12+'12'!AM12+'13'!AM12+'14'!AM12+'15'!AM12+'16'!AM12+'17'!AM12+'18'!AM12+'19'!AM12+'20'!AM12+'21'!AM12+'22'!AM12+'23'!AM12+'24'!AM12+'25'!AM12+'26'!AM12+'27'!AM12+'28'!AM12+'29'!AM12+'30'!AM12+'31'!AM12 -> 0 | O15: =+'1'!AN12+'2'!AN12+'3'!AN12+'4'!AN12+'5'!AN12+'6'!AN12+'7'!AN12+'8'!AN12+'9'!AN12+'10'!AN12+'11'!AN12+'12'!AN12+'13'!AN12+'14'!AN12+'15'!AN12+'16'!AN12+'17'!AN12+'18'!AN12+'19'!AN12+'20'!AN12+'21'!AN12+'22'!AN12+'23'!AN12+'24'!AN12+'25'!AN12+'26'!AN12+'27'!AN12+'28'!AN12+'29'!AN12+'30'!AN12+'31'!AN12 -> 0 | P15: =+'1'!AO12+'2'!AO12+'3'!AO12+'4'!AO12+'5'!AO12+'6'!AO12+'7'!AO12+'8'!AO12+'9'!AO12+'10'!AO12+'11'!AO12+'12'!AO12+'13'!AO12+'14'!AO12+'15'!AO12+'16'!AO12+'17'!AO12+'18'!AO12+'19'!AO12+'20'!AO12+'21'!AO12+'22'!AO12+'23'!AO12+'24'!AO12+'25'!AO12+'26'!AO12+'27'!AO12+'28'!AO12+'29'!AO12+'30'!AO12+'31'!AO12 -> 0 | ... W15: =+'1'!AV12+'2'!AV12+'3'!AV12+'4'!AV12+'5'!AV12+'6'!AV12+'7'!AV12+'8'!AV12+'9'!AV12+'10'!AV12+'11'!AV12+'12'!AV12+'13'!AV12+'14'!AV12+'15'!AV12+'16'!AV12+'17'!AV12+'18'!AV12+'19'!AV12+'20'!AV12+'21'!AV12+'22'!AV12+'23'!AV12+'24'!AV12+'25'!AV12+'26'!AV12+'27'!AV12+'28'!AV12+'29'!AV12+'30'!AV12+'31'!AV12 -> 0
C17: A/D 완료품 검사 현황 | E17: =SUM(E8:E15) -> 9458 | F17: =SUM(F8:F15) -> 9007 | G17: =SUM(G8:G15) -> 451 | H17: =IF(E17=0,"",G17/E17) -> 0.0476845 | I17: =SUM(I8:I15) -> 1 | J17: =SUM(J8:J15) -> 26 | K17: =SUM(K8:K15) -> 6 | L17: =SUM(L8:L15) -> 3 | M17: =SUM(M8:M15) -> 0 | N17: =SUM(N8:N15) -> 0 | O17: =SUM(O8:O15) -> 125 | P17: =SUM(P8:P15) -> 5 | ... W17: =SUM(W8:W15) -> 0
B19: 회사명 | C19: 모델 | E19: 작업수량 | F19: 양품 | G19: 불량 | H19: 불량율 | I19: 불량내역
I20: S/C | J20: 찍힘 | K20: A/D얼룩 | L20: H/L | M20: 휨 | O20: 기포 | P20: 소재 | Q20: 툴자국 | R20: 가공 | U20: 이물 | V20: 코팅얼룩 | W20: 시료
B21: 태산 | C21: 61MM | D21: KA4 | E21: =+'1'!AD14+'2'!AD14+'3'!AD14+'4'!AD14+'5'!AD14+'6'!AD14+'7'!AD14+'8'!AD14+'9'!AD14+'10'!AD14+'11'!AD14+'12'!AD14+'13'!AD14+'14'!AD14+'15'!AD14+'16'!AD14+'17'!AD14+'18'!AD14+'19'!AD14+'20'!AD14+'21'!AD14+'22'!AD14+'23'!AD14+'24'!AD14+'25'!AD14+'26'!AD14+'27'!AD14+'28'!AD14+'29'!AD14+'30'!AD14+'31'!AD14 -> 0 | F21: =+'1'!AE14+'2'!AE14+'3'!AE14+'4'!AE14+'5'!AE14+'6'!AE14+'7'!AE14+'8'!AE14+'9'!AE14+'10'!AE14+'11'!AE14+'12'!AE14+'13'!AE14+'14'!AE14+'15'!AE14+'16'!AE14+'17'!AE14+'18'!AE14+'19'!AE14+'20'!AE14+'21'!AE14+'22'!AE14+'23'!AE14+'24'!AE14+'25'!AE14+'26'!AE14+'27'!AE14+'28'!AE14+'29'!AE14+'30'!AE14+'31'!AE14 -> 0 | G21: =+'1'!AF14+'2'!AF14+'3'!AF14+'4'!AF14+'5'!AF14+'6'!AF14+'7'!AF14+'8'!AF14+'9'!AF14+'10'!AF14+'11'!AF14+'12'!AF14+'13'!AF14+'14'!AF14+'15'!AF14+'16'!AF14+'17'!AF14+'18'!AF14+'19'!AF14+'20'!AF14+'21'!AF14+'22'!AF14+'23'!AF14+'24'!AF14+'25'!AF14+'26'!AF14+'27'!AF14+'28'!AF14+'29'!AF14+'30'!AF14+'31'!AF14 -> 0 | H21: =IF(E21=0,"",G21/E21) | I21: =+'1'!AH14+'2'!AH14+'3'!AH14+'4'!AH14+'5'!AH14+'6'!AH14+'7'!AH14+'8'!AH14+'9'!AH14+'10'!AH14+'11'!AH14+'12'!AH14+'13'!AH14+'14'!AH14+'15'!AH14+'16'!AH14+'17'!AH14+'18'!AH14+'19'!AH14+'20'!AH14+'21'!AH14+'22'!AH14+'23'!AH14+'24'!AH14+'25'!AH14+'26'!AH14+'27'!AH14+'28'!AH14+'29'!AH14+'30'!AH14+'31'!AH14 -> 0 | J21: =+'1'!AI14+'2'!AI14+'3'!AI14+'4'!AI14+'5'!AI14+'6'!AI14+'7'!AI14+'8'!AI14+'9'!AI14+'10'!AI14+'11'!AI14+'12'!AI14+'13'!AI14+'14'!AI14+'15'!AI14+'16'!AI14+'17'!AI14+'18'!AI14+'19'!AI14+'20'!AI14+'21'!AI14+'22'!AI14+'23'!AI14+'24'!AI14+'25'!AI14+'26'!AI14+'27'!AI14+'28'!AI14+'29'!AI14+'30'!AI14+'31'!AI14 -> 0 | K21: =+'1'!AJ14+'2'!AJ14+'3'!AJ14+'4'!AJ14+'5'!AJ14+'6'!AJ14+'7'!AJ14+'8'!AJ14+'9'!AJ14+'10'!AJ14+'11'!AJ14+'12'!AJ14+'13'!AJ14+'14'!AJ14+'15'!AJ14+'16'!AJ14+'17'!AJ14+'18'!AJ14+'19'!AJ14+'20'!AJ14+'21'!AJ14+'22'!AJ14+'23'!AJ14+'24'!AJ14+'25'!AJ14+'26'!AJ14+'27'!AJ14+'28'!AJ14+'29'!AJ14+'30'!AJ14+'31'!AJ14 -> 0 | L21: =+'1'!AK14+'2'!AK14+'3'!AK14+'4'!AK14+'5'!AK14+'6'!AK14+'7'!AK14+'8'!AK14+'9'!AK14+'10'!AK14+'11'!AK14+'12'!AK14+'13'!AK14+'14'!AK14+'15'!AK14+'16'!AK14+'17'!AK14+'18'!AK14+'19'!AK14+'20'!AK14+'21'!AK14+'22'!AK14+'23'!AK14+'24'!AK14+'25'!AK14+'26'!AK14+'27'!AK14+'28'!AK14+'29'!AK14+'30'!AK14+'31'!AK14 -> 0 | M21: =+'1'!AL14+'2'!AL14+'3'!AL14+'4'!AL14+'5'!AL14+'6'!AL14+'7'!AL14+'8'!AL14+'9'!AL14+'10'!AL14+'11'!AL14+'12'!AL14+'13'!AL14+'14'!AL14+'15'!AL14+'16'!AL14+'17'!AL14+'18'!AL14+'19'!AL14+'20'!AL14+'21'!AL14+'22'!AL14+'23'!AL14+'24'!AL14+'25'!AL14+'26'!AL14+'27'!AL14+'28'!AL14+'29'!AL14+'30'!AL14+'31'!AL14 -> 0 | N21: =+'1'!AM14+'2'!AM14+'3'!AM14+'4'!AM14+'5'!AM14+'6'!AM14+'7'!AM14+'8'!AM14+'9'!AM14+'10'!AM14+'11'!AM14+'12'!AM14+'13'!AM14+'14'!AM14+'15'!AM14+'16'!AM14+'17'!AM14+'18'!AM14+'19'!AM14+'20'!AM14+'21'!AM14+'22'!AM14+'23'!AM14+'24'!AM14+'25'!AM14+'26'!AM14+'27'!AM14+'28'!AM14+'29'!AM14+'30'!AM14+'31'!AM14 -> 0 | O21: =+'1'!AN14+'2'!AN14+'3'!AN14+'4'!AN14+'5'!AN14+'6'!AN14+'7'!AN14+'8'!AN14+'9'!AN14+'10'!AN14+'11'!AN14+'12'!AN14+'13'!AN14+'14'!AN14+'15'!AN14+'16'!AN14+'17'!AN14+'18'!AN14+'19'!AN14+'20'!AN14+'21'!AN14+'22'!AN14+'23'!AN14+'24'!AN14+'25'!AN14+'26'!AN14+'27'!AN14+'28'!AN14+'29'!AN14+'30'!AN14+'31'!AN14 -> 0 | P21: =+'1'!AO14+'2'!AO14+'3'!AO14+'4'!AO14+'5'!AO14+'6'!AO14+'7'!AO14+'8'!AO14+'9'!AO14+'10'!AO14+'11'!AO14+'12'!AO14+'13'!AO14+'14'!AO14+'15'!AO14+'16'!AO14+'17'!AO14+'18'!AO14+'19'!AO14+'20'!AO14+'21'!AO14+'22'!AO14+'23'!AO14+'24'!AO14+'25'!AO14+'26'!AO14+'27'!AO14+'28'!AO14+'29'!AO14+'30'!AO14+'31'!AO14 -> 0 | ... W21: =+'1'!AV14+'2'!AV14+'3'!AV14+'4'!AV14+'5'!AV14+'6'!AV14+'7'!AV14+'8'!AV14+'9'!AV14+'10'!AV14+'11'!AV14+'12'!AV14+'13'!AV14+'14'!AV14+'15'!AV14+'16'!AV14+'17'!AV14+'18'!AV14+'19'!AV14+'20'!AV14+'21'!AV14+'22'!AV14+'23'!AV14+'24'!AV14+'25'!AV14+'26'!AV14+'27'!AV14+'28'!AV14+'29'!AV14+'30'!AV14+'31'!AV14 -> 0
C22: 71MM | D22: GL3 | E22: =+'1'!AD15+'2'!AD15+'3'!AD15+'4'!AD15+'5'!AD15+'6'!AD15+'7'!AD15+'8'!AD15+'9'!AD15+'10'!AD15+'11'!AD15+'12'!AD15+'13'!AD15+'14'!AD15+'15'!AD15+'16'!AD15+'17'!AD15+'18'!AD15+'19'!AD15+'20'!AD15+'21'!AD15+'22'!AD15+'23'!AD15+'24'!AD15+'25'!AD15+'26'!AD15+'27'!AD15+'28'!AD15+'29'!AD15+'30'!AD15+'31'!AD15 -> 0 | F22: =+'1'!AE15+'2'!AE15+'3'!AE15+'4'!AE15+'5'!AE15+'6'!AE15+'7'!AE15+'8'!AE15+'9'!AE15+'10'!AE15+'11'!AE15+'12'!AE15+'13'!AE15+'14'!AE15+'15'!AE15+'16'!AE15+'17'!AE15+'18'!AE15+'19'!AE15+'20'!AE15+'21'!AE15+'22'!AE15+'23'!AE15+'24'!AE15+'25'!AE15+'26'!AE15+'27'!AE15+'28'!AE15+'29'!AE15+'30'!AE15+'31'!AE15 -> 0 | G22: =+'1'!AF15+'2'!AF15+'3'!AF15+'4'!AF15+'5'!AF15+'6'!AF15+'7'!AF15+'8'!AF15+'9'!AF15+'10'!AF15+'11'!AF15+'12'!AF15+'13'!AF15+'14'!AF15+'15'!AF15+'16'!AF15+'17'!AF15+'18'!AF15+'19'!AF15+'20'!AF15+'21'!AF15+'22'!AF15+'23'!AF15+'24'!AF15+'25'!AF15+'26'!AF15+'27'!AF15+'28'!AF15+'29'!AF15+'30'!AF15+'31'!AF15 -> 0 | H22: =IF(E22=0,"",G22/E22) | I22: =+'1'!AH15+'2'!AH15+'3'!AH15+'4'!AH15+'5'!AH15+'6'!AH15+'7'!AH15+'8'!AH15+'9'!AH15+'10'!AH15+'11'!AH15+'12'!AH15+'13'!AH15+'14'!AH15+'15'!AH15+'16'!AH15+'17'!AH15+'18'!AH15+'19'!AH15+'20'!AH15+'21'!AH15+'22'!AH15+'23'!AH15+'24'!AH15+'25'!AH15+'26'!AH15+'27'!AH15+'28'!AH15+'29'!AH15+'30'!AH15+'31'!AH15 -> 0 | J22: =+'1'!AI15+'2'!AI15+'3'!AI15+'4'!AI15+'5'!AI15+'6'!AI15+'7'!AI15+'8'!AI15+'9'!AI15+'10'!AI15+'11'!AI15+'12'!AI15+'13'!AI15+'14'!AI15+'15'!AI15+'16'!AI15+'17'!AI15+'18'!AI15+'19'!AI15+'20'!AI15+'21'!AI15+'22'!AI15+'23'!AI15+'24'!AI15+'25'!AI15+'26'!AI15+'27'!AI15+'28'!AI15+'29'!AI15+'30'!AI15+'31'!AI15 -> 0 | K22: =+'1'!AJ15+'2'!AJ15+'3'!AJ15+'4'!AJ15+'5'!AJ15+'6'!AJ15+'7'!AJ15+'8'!AJ15+'9'!AJ15+'10'!AJ15+'11'!AJ15+'12'!AJ15+'13'!AJ15+'14'!AJ15+'15'!AJ15+'16'!AJ15+'17'!AJ15+'18'!AJ15+'19'!AJ15+'20'!AJ15+'21'!AJ15+'22'!AJ15+'23'!AJ15+'24'!AJ15+'25'!AJ15+'26'!AJ15+'27'!AJ15+'28'!AJ15+'29'!AJ15+'30'!AJ15+'31'!AJ15 -> 0 | L22: =+'1'!AK15+'2'!AK15+'3'!AK15+'4'!AK15+'5'!AK15+'6'!AK15+'7'!AK15+'8'!AK15+'9'!AK15+'10'!AK15+'11'!AK15+'12'!AK15+'13'!AK15+'14'!AK15+'15'!AK15+'16'!AK15+'17'!AK15+'18'!AK15+'19'!AK15+'20'!AK15+'21'!AK15+'22'!AK15+'23'!AK15+'24'!AK15+'25'!AK15+'26'!AK15+'27'!AK15+'28'!AK15+'29'!AK15+'30'!AK15+'31'!AK15 -> 0 | M22: =+'1'!AL15+'2'!AL15+'3'!AL15+'4'!AL15+'5'!AL15+'6'!AL15+'7'!AL15+'8'!AL15+'9'!AL15+'10'!AL15+'11'!AL15+'12'!AL15+'13'!AL15+'14'!AL15+'15'!AL15+'16'!AL15+'17'!AL15+'18'!AL15+'19'!AL15+'20'!AL15+'21'!AL15+'22'!AL15+'23'!AL15+'24'!AL15+'25'!AL15+'26'!AL15+'27'!AL15+'28'!AL15+'29'!AL15+'30'!AL15+'31'!AL15 -> 0 | N22: =+'1'!AM15+'2'!AM15+'3'!AM15+'4'!AM15+'5'!AM15+'6'!AM15+'7'!AM15+'8'!AM15+'9'!AM15+'10'!AM15+'11'!AM15+'12'!AM15+'13'!AM15+'14'!AM15+'15'!AM15+'16'!AM15+'17'!AM15+'18'!AM15+'19'!AM15+'20'!AM15+'21'!AM15+'22'!AM15+'23'!AM15+'24'!AM15+'25'!AM15+'26'!AM15+'27'!AM15+'28'!AM15+'29'!AM15+'30'!AM15+'31'!AM15 -> 0 | O22: =+'1'!AN15+'2'!AN15+'3'!AN15+'4'!AN15+'5'!AN15+'6'!AN15+'7'!AN15+'8'!AN15+'9'!AN15+'10'!AN15+'11'!AN15+'12'!AN15+'13'!AN15+'14'!AN15+'15'!AN15+'16'!AN15+'17'!AN15+'18'!AN15+'19'!AN15+'20'!AN15+'21'!AN15+'22'!AN15+'23'!AN15+'24'!AN15+'25'!AN15+'26'!AN15+'27'!AN15+'28'!AN15+'29'!AN15+'30'!AN15+'31'!AN15 -> 0 | P22: =+'1'!AO15+'2'!AO15+'3'!AO15+'4'!AO15+'5'!AO15+'6'!AO15+'7'!AO15+'8'!AO15+'9'!AO15+'10'!AO15+'11'!AO15+'12'!AO15+'13'!AO15+'14'!AO15+'15'!AO15+'16'!AO15+'17'!AO15+'18'!AO15+'19'!AO15+'20'!AO15+'21'!AO15+'22'!AO15+'23'!AO15+'24'!AO15+'25'!AO15+'26'!AO15+'27'!AO15+'28'!AO15+'29'!AO15+'30'!AO15+'31'!AO15 -> 0 | ... W22: =+'1'!AV15+'2'!AV15+'3'!AV15+'4'!AV15+'5'!AV15+'6'!AV15+'7'!AV15+'8'!AV15+'9'!AV15+'10'!AV15+'11'!AV15+'12'!AV15+'13'!AV15+'14'!AV15+'15'!AV15+'16'!AV15+'17'!AV15+'18'!AV15+'19'!AV15+'20'!AV15+'21'!AV15+'22'!AV15+'23'!AV15+'24'!AV15+'25'!AV15+'26'!AV15+'27'!AV15+'28'!AV15+'29'!AV15+'30'!AV15+'31'!AV15 -> 0
C23: H EMBLEM | D23: CN7 PE | E23: =+'1'!AD16+'2'!AD16+'3'!AD16+'4'!AD16+'5'!AD16+'6'!AD16+'7'!AD16+'8'!AD16+'9'!AD16+'10'!AD16+'11'!AD16+'12'!AD16+'13'!AD16+'14'!AD16+'15'!AD16+'16'!AD16+'17'!AD16+'18'!AD16+'19'!AD16+'20'!AD16+'21'!AD16+'22'!AD16+'23'!AD16+'24'!AD16+'25'!AD16+'26'!AD16+'27'!AD16+'28'!AD16+'29'!AD16+'30'!AD16+'31'!AD16 -> 7170 | F23: =+'1'!AE16+'2'!AE16+'3'!AE16+'4'!AE16+'5'!AE16+'6'!AE16+'7'!AE16+'8'!AE16+'9'!AE16+'10'!AE16+'11'!AE16+'12'!AE16+'13'!AE16+'14'!AE16+'15'!AE16+'16'!AE16+'17'!AE16+'18'!AE16+'19'!AE16+'20'!AE16+'21'!AE16+'22'!AE16+'23'!AE16+'24'!AE16+'25'!AE16+'26'!AE16+'27'!AE16+'28'!AE16+'29'!AE16+'30'!AE16+'31'!AE16 -> 7013 | G23: =+'1'!AF16+'2'!AF16+'3'!AF16+'4'!AF16+'5'!AF16+'6'!AF16+'7'!AF16+'8'!AF16+'9'!AF16+'10'!AF16+'11'!AF16+'12'!AF16+'13'!AF16+'14'!AF16+'15'!AF16+'16'!AF16+'17'!AF16+'18'!AF16+'19'!AF16+'20'!AF16+'21'!AF16+'22'!AF16+'23'!AF16+'24'!AF16+'25'!AF16+'26'!AF16+'27'!AF16+'28'!AF16+'29'!AF16+'30'!AF16+'31'!AF16 -> 157 | H23: =IF(E23=0,"",G23/E23) -> 0.021896792 | I23: =+'1'!AH16+'2'!AH16+'3'!AH16+'4'!AH16+'5'!AH16+'6'!AH16+'7'!AH16+'8'!AH16+'9'!AH16+'10'!AH16+'11'!AH16+'12'!AH16+'13'!AH16+'14'!AH16+'15'!AH16+'16'!AH16+'17'!AH16+'18'!AH16+'19'!AH16+'20'!AH16+'21'!AH16+'22'!AH16+'23'!AH16+'24'!AH16+'25'!AH16+'26'!AH16+'27'!AH16+'28'!AH16+'29'!AH16+'30'!AH16+'31'!AH16 -> 14 | J23: =+'1'!AI16+'2'!AI16+'3'!AI16+'4'!AI16+'5'!AI16+'6'!AI16+'7'!AI16+'8'!AI16+'9'!AI16+'10'!AI16+'11'!AI16+'12'!AI16+'13'!AI16+'14'!AI16+'15'!AI16+'16'!AI16+'17'!AI16+'18'!AI16+'19'!AI16+'20'!AI16+'21'!AI16+'22'!AI16+'23'!AI16+'24'!AI16+'25'!AI16+'26'!AI16+'27'!AI16+'28'!AI16+'29'!AI16+'30'!AI16+'31'!AI16 -> 28 | K23: =+'1'!AJ16+'2'!AJ16+'3'!AJ16+'4'!AJ16+'5'!AJ16+'6'!AJ16+'7'!AJ16+'8'!AJ16+'9'!AJ16+'10'!AJ16+'11'!AJ16+'12'!AJ16+'13'!AJ16+'14'!AJ16+'15'!AJ16+'16'!AJ16+'17'!AJ16+'18'!AJ16+'19'!AJ16+'20'!AJ16+'21'!AJ16+'22'!AJ16+'23'!AJ16+'24'!AJ16+'25'!AJ16+'26'!AJ16+'27'!AJ16+'28'!AJ16+'29'!AJ16+'30'!AJ16+'31'!AJ16 -> 0 | L23: =+'1'!AK16+'2'!AK16+'3'!AK16+'4'!AK16+'5'!AK16+'6'!AK16+'7'!AK16+'8'!AK16+'9'!AK16+'10'!AK16+'11'!AK16+'12'!AK16+'13'!AK16+'14'!AK16+'15'!AK16+'16'!AK16+'17'!AK16+'18'!AK16+'19'!AK16+'20'!AK16+'21'!AK16+'22'!AK16+'23'!AK16+'24'!AK16+'25'!AK16+'26'!AK16+'27'!AK16+'28'!AK16+'29'!AK16+'30'!AK16+'31'!AK16 -> 5 | M23: =+'1'!AL16+'2'!AL16+'3'!AL16+'4'!AL16+'5'!AL16+'6'!AL16+'7'!AL16+'8'!AL16+'9'!AL16+'10'!AL16+'11'!AL16+'12'!AL16+'13'!AL16+'14'!AL16+'15'!AL16+'16'!AL16+'17'!AL16+'18'!AL16+'19'!AL16+'20'!AL16+'21'!AL16+'22'!AL16+'23'!AL16+'24'!AL16+'25'!AL16+'26'!AL16+'27'!AL16+'28'!AL16+'29'!AL16+'30'!AL16+'31'!AL16 -> 0 | N23: =+'1'!AM16+'2'!AM16+'3'!AM16+'4'!AM16+'5'!AM16+'6'!AM16+'7'!AM16+'8'!AM16+'9'!AM16+'10'!AM16+'11'!AM16+'12'!AM16+'13'!AM16+'14'!AM16+'15'!AM16+'16'!AM16+'17'!AM16+'18'!AM16+'19'!AM16+'20'!AM16+'21'!AM16+'22'!AM16+'23'!AM16+'24'!AM16+'25'!AM16+'26'!AM16+'27'!AM16+'28'!AM16+'29'!AM16+'30'!AM16+'31'!AM16 -> 0 | O23: =+'1'!AN16+'2'!AN16+'3'!AN16+'4'!AN16+'5'!AN16+'6'!AN16+'7'!AN16+'8'!AN16+'9'!AN16+'10'!AN16+'11'!AN16+'12'!AN16+'13'!AN16+'14'!AN16+'15'!AN16+'16'!AN16+'17'!AN16+'18'!AN16+'19'!AN16+'20'!AN16+'21'!AN16+'22'!AN16+'23'!AN16+'24'!AN16+'25'!AN16+'26'!AN16+'27'!AN16+'28'!AN16+'29'!AN16+'30'!AN16+'31'!AN16 -> 0 | P23: =+'1'!AO16+'2'!AO16+'3'!AO16+'4'!AO16+'5'!AO16+'6'!AO16+'7'!AO16+'8'!AO16+'9'!AO16+'10'!AO16+'11'!AO16+'12'!AO16+'13'!AO16+'14'!AO16+'15'!AO16+'16'!AO16+'17'!AO16+'18'!AO16+'19'!AO16+'20'!AO16+'21'!AO16+'22'!AO16+'23'!AO16+'24'!AO16+'25'!AO16+'26'!AO16+'27'!AO16+'28'!AO16+'29'!AO16+'30'!AO16+'31'!AO16 -> 0 | ... W23: =+'1'!AV16+'2'!AV16+'3'!AV16+'4'!AV16+'5'!AV16+'6'!AV16+'7'!AV16+'8'!AV16+'9'!AV16+'10'!AV16+'11'!AV16+'12'!AV16+'13'!AV16+'14'!AV16+'15'!AV16+'16'!AV16+'17'!AV16+'18'!AV16+'19'!AV16+'20'!AV16+'21'!AV16+'22'!AV16+'23'!AV16+'24'!AV16+'25'!AV16+'26'!AV16+'27'!AV16+'28'!AV16+'29'!AV16+'30'!AV16+'31'!AV16 -> 3
C24: GN7 BEZEL | D24: GN7 | E24: =+'1'!AD17+'2'!AD17+'3'!AD17+'4'!AD17+'5'!AD17+'6'!AD17+'7'!AD17+'8'!AD17+'9'!AD17+'10'!AD17+'11'!AD17+'12'!AD17+'13'!AD17+'14'!AD17+'15'!AD17+'16'!AD17+'17'!AD17+'18'!AD17+'19'!AD17+'20'!AD17+'21'!AD17+'22'!AD17+'23'!AD17+'24'!AD17+'25'!AD17+'26'!AD17+'27'!AD17+'28'!AD17+'29'!AD17+'30'!AD17+'31'!AD17 -> 0 | F24: =+'1'!AE17+'2'!AE17+'3'!AE17+'4'!AE17+'5'!AE17+'6'!AE17+'7'!AE17+'8'!AE17+'9'!AE17+'10'!AE17+'11'!AE17+'12'!AE17+'13'!AE17+'14'!AE17+'15'!AE17+'16'!AE17+'17'!AE17+'18'!AE17+'19'!AE17+'20'!AE17+'21'!AE17+'22'!AE17+'23'!AE17+'24'!AE17+'25'!AE17+'26'!AE17+'27'!AE17+'28'!AE17+'29'!AE17+'30'!AE17+'31'!AE17 -> 0 | G24: =+'1'!AF17+'2'!AF17+'3'!AF17+'4'!AF17+'5'!AF17+'6'!AF17+'7'!AF17+'8'!AF17+'9'!AF17+'10'!AF17+'11'!AF17+'12'!AF17+'13'!AF17+'14'!AF17+'15'!AF17+'16'!AF17+'17'!AF17+'18'!AF17+'19'!AF17+'20'!AF17+'21'!AF17+'22'!AF17+'23'!AF17+'24'!AF17+'25'!AF17+'26'!AF17+'27'!AF17+'28'!AF17+'29'!AF17+'30'!AF17+'31'!AF17 -> 0 | H24: =IF(E24=0,"",G24/E24) | I24: =+'1'!AH17+'2'!AH17+'3'!AH17+'4'!AH17+'5'!AH17+'6'!AH17+'7'!AH17+'8'!AH17+'9'!AH17+'10'!AH17+'11'!AH17+'12'!AH17+'13'!AH17+'14'!AH17+'15'!AH17+'16'!AH17+'17'!AH17+'18'!AH17+'19'!AH17+'20'!AH17+'21'!AH17+'22'!AH17+'23'!AH17+'24'!AH17+'25'!AH17+'26'!AH17+'27'!AH17+'28'!AH17+'29'!AH17+'30'!AH17+'31'!AH17 -> 0 | J24: =+'1'!AI17+'2'!AI17+'3'!AI17+'4'!AI17+'5'!AI17+'6'!AI17+'7'!AI17+'8'!AI17+'9'!AI17+'10'!AI17+'11'!AI17+'12'!AI17+'13'!AI17+'14'!AI17+'15'!AI17+'16'!AI17+'17'!AI17+'18'!AI17+'19'!AI17+'20'!AI17+'21'!AI17+'22'!AI17+'23'!AI17+'24'!AI17+'25'!AI17+'26'!AI17+'27'!AI17+'28'!AI17+'29'!AI17+'30'!AI17+'31'!AI17 -> 0 | K24: =+'1'!AJ17+'2'!AJ17+'3'!AJ17+'4'!AJ17+'5'!AJ17+'6'!AJ17+'7'!AJ17+'8'!AJ17+'9'!AJ17+'10'!AJ17+'11'!AJ17+'12'!AJ17+'13'!AJ17+'14'!AJ17+'15'!AJ17+'16'!AJ17+'17'!AJ17+'18'!AJ17+'19'!AJ17+'20'!AJ17+'21'!AJ17+'22'!AJ17+'23'!AJ17+'24'!AJ17+'25'!AJ17+'26'!AJ17+'27'!AJ17+'28'!AJ17+'29'!AJ17+'30'!AJ17+'31'!AJ17 -> 0 | L24: =+'1'!AK17+'2'!AK17+'3'!AK17+'4'!AK17+'5'!AK17+'6'!AK17+'7'!AK17+'8'!AK17+'9'!AK17+'10'!AK17+'11'!AK17+'12'!AK17+'13'!AK17+'14'!AK17+'15'!AK17+'16'!AK17+'17'!AK17+'18'!AK17+'19'!AK17+'20'!AK17+'21'!AK17+'22'!AK17+'23'!AK17+'24'!AK17+'25'!AK17+'26'!AK17+'27'!AK17+'28'!AK17+'29'!AK17+'30'!AK17+'31'!AK17 -> 0 | M24: =+'1'!AL17+'2'!AL17+'3'!AL17+'4'!AL17+'5'!AL17+'6'!AL17+'7'!AL17+'8'!AL17+'9'!AL17+'10'!AL17+'11'!AL17+'12'!AL17+'13'!AL17+'14'!AL17+'15'!AL17+'16'!AL17+'17'!AL17+'18'!AL17+'19'!AL17+'20'!AL17+'21'!AL17+'22'!AL17+'23'!AL17+'24'!AL17+'25'!AL17+'26'!AL17+'27'!AL17+'28'!AL17+'29'!AL17+'30'!AL17+'31'!AL17 -> 0 | N24: =+'1'!AM17+'2'!AM17+'3'!AM17+'4'!AM17+'5'!AM17+'6'!AM17+'7'!AM17+'8'!AM17+'9'!AM17+'10'!AM17+'11'!AM17+'12'!AM17+'13'!AM17+'14'!AM17+'15'!AM17+'16'!AM17+'17'!AM17+'18'!AM17+'19'!AM17+'20'!AM17+'21'!AM17+'22'!AM17+'23'!AM17+'24'!AM17+'25'!AM17+'26'!AM17+'27'!AM17+'28'!AM17+'29'!AM17+'30'!AM17+'31'!AM17 -> 0 | O24: =+'1'!AN17+'2'!AN17+'3'!AN17+'4'!AN17+'5'!AN17+'6'!AN17+'7'!AN17+'8'!AN17+'9'!AN17+'10'!AN17+'11'!AN17+'12'!AN17+'13'!AN17+'14'!AN17+'15'!AN17+'16'!AN17+'17'!AN17+'18'!AN17+'19'!AN17+'20'!AN17+'21'!AN17+'22'!AN17+'23'!AN17+'24'!AN17+'25'!AN17+'26'!AN17+'27'!AN17+'28'!AN17+'29'!AN17+'30'!AN17+'31'!AN17 -> 0 | P24: =+'1'!AO17+'2'!AO17+'3'!AO17+'4'!AO17+'5'!AO17+'6'!AO17+'7'!AO17+'8'!AO17+'9'!AO17+'10'!AO17+'11'!AO17+'12'!AO17+'13'!AO17+'14'!AO17+'15'!AO17+'16'!AO17+'17'!AO17+'18'!AO17+'19'!AO17+'20'!AO17+'21'!AO17+'22'!AO17+'23'!AO17+'24'!AO17+'25'!AO17+'26'!AO17+'27'!AO17+'28'!AO17+'29'!AO17+'30'!AO17+'31'!AO17 -> 0 | ... W24: =+'1'!AV17+'2'!AV17+'3'!AV17+'4'!AV17+'5'!AV17+'6'!AV17+'7'!AV17+'8'!AV17+'9'!AV17+'10'!AV17+'11'!AV17+'12'!AV17+'13'!AV17+'14'!AV17+'15'!AV17+'16'!AV17+'17'!AV17+'18'!AV17+'19'!AV17+'20'!AV17+'21'!AV17+'22'!AV17+'23'!AV17+'24'!AV17+'25'!AV17+'26'!AV17+'27'!AV17+'28'!AV17+'29'!AV17+'30'!AV17+'31'!AV17 -> 0
C25: 45MM | D25: CL4 | E25: =+'1'!AD18+'2'!AD18+'3'!AD18+'4'!AD18+'5'!AD18+'6'!AD18+'7'!AD18+'8'!AD18+'9'!AD18+'10'!AD18+'11'!AD18+'12'!AD18+'13'!AD18+'14'!AD18+'15'!AD18+'16'!AD18+'17'!AD18+'18'!AD18+'19'!AD18+'20'!AD18+'21'!AD18+'22'!AD18+'23'!AD18+'24'!AD18+'25'!AD18+'26'!AD18+'27'!AD18+'28'!AD18+'29'!AD18+'30'!AD18+'31'!AD18 -> 0 | F25: =+'1'!AE18+'2'!AE18+'3'!AE18+'4'!AE18+'5'!AE18+'6'!AE18+'7'!AE18+'8'!AE18+'9'!AE18+'10'!AE18+'11'!AE18+'12'!AE18+'13'!AE18+'14'!AE18+'15'!AE18+'16'!AE18+'17'!AE18+'18'!AE18+'19'!AE18+'20'!AE18+'21'!AE18+'22'!AE18+'23'!AE18+'24'!AE18+'25'!AE18+'26'!AE18+'27'!AE18+'28'!AE18+'29'!AE18+'30'!AE18+'31'!AE18 -> 0 | G25: =+'1'!AF18+'2'!AF18+'3'!AF18+'4'!AF18+'5'!AF18+'6'!AF18+'7'!AF18+'8'!AF18+'9'!AF18+'10'!AF18+'11'!AF18+'12'!AF18+'13'!AF18+'14'!AF18+'15'!AF18+'16'!AF18+'17'!AF18+'18'!AF18+'19'!AF18+'20'!AF18+'21'!AF18+'22'!AF18+'23'!AF18+'24'!AF18+'25'!AF18+'26'!AF18+'27'!AF18+'28'!AF18+'29'!AF18+'30'!AF18+'31'!AF18 -> 0 | H25: =IF(E25=0,"",G25/E25) | I25: =+'1'!AH18+'2'!AH18+'3'!AH18+'4'!AH18+'5'!AH18+'6'!AH18+'7'!AH18+'8'!AH18+'9'!AH18+'10'!AH18+'11'!AH18+'12'!AH18+'13'!AH18+'14'!AH18+'15'!AH18+'16'!AH18+'17'!AH18+'18'!AH18+'19'!AH18+'20'!AH18+'21'!AH18+'22'!AH18+'23'!AH18+'24'!AH18+'25'!AH18+'26'!AH18+'27'!AH18+'28'!AH18+'29'!AH18+'30'!AH18+'31'!AH18 -> 0 | J25: =+'1'!AI18+'2'!AI18+'3'!AI18+'4'!AI18+'5'!AI18+'6'!AI18+'7'!AI18+'8'!AI18+'9'!AI18+'10'!AI18+'11'!AI18+'12'!AI18+'13'!AI18+'14'!AI18+'15'!AI18+'16'!AI18+'17'!AI18+'18'!AI18+'19'!AI18+'20'!AI18+'21'!AI18+'22'!AI18+'23'!AI18+'24'!AI18+'25'!AI18+'26'!AI18+'27'!AI18+'28'!AI18+'29'!AI18+'30'!AI18+'31'!AI18 -> 0 | K25: =+'1'!AJ18+'2'!AJ18+'3'!AJ18+'4'!AJ18+'5'!AJ18+'6'!AJ18+'7'!AJ18+'8'!AJ18+'9'!AJ18+'10'!AJ18+'11'!AJ18+'12'!AJ18+'13'!AJ18+'14'!AJ18+'15'!AJ18+'16'!AJ18+'17'!AJ18+'18'!AJ18+'19'!AJ18+'20'!AJ18+'21'!AJ18+'22'!AJ18+'23'!AJ18+'24'!AJ18+'25'!AJ18+'26'!AJ18+'27'!AJ18+'28'!AJ18+'29'!AJ18+'30'!AJ18+'31'!AJ18 -> 0 | L25: =+'1'!AK18+'2'!AK18+'3'!AK18+'4'!AK18+'5'!AK18+'6'!AK18+'7'!AK18+'8'!AK18+'9'!AK18+'10'!AK18+'11'!AK18+'12'!AK18+'13'!AK18+'14'!AK18+'15'!AK18+'16'!AK18+'17'!AK18+'18'!AK18+'19'!AK18+'20'!AK18+'21'!AK18+'22'!AK18+'23'!AK18+'24'!AK18+'25'!AK18+'26'!AK18+'27'!AK18+'28'!AK18+'29'!AK18+'30'!AK18+'31'!AK18 -> 0 | M25: =+'1'!AL18+'2'!AL18+'3'!AL18+'4'!AL18+'5'!AL18+'6'!AL18+'7'!AL18+'8'!AL18+'9'!AL18+'10'!AL18+'11'!AL18+'12'!AL18+'13'!AL18+'14'!AL18+'15'!AL18+'16'!AL18+'17'!AL18+'18'!AL18+'19'!AL18+'20'!AL18+'21'!AL18+'22'!AL18+'23'!AL18+'24'!AL18+'25'!AL18+'26'!AL18+'27'!AL18+'28'!AL18+'29'!AL18+'30'!AL18+'31'!AL18 -> 0 | N25: =+'1'!AM18+'2'!AM18+'3'!AM18+'4'!AM18+'5'!AM18+'6'!AM18+'7'!AM18+'8'!AM18+'9'!AM18+'10'!AM18+'11'!AM18+'12'!AM18+'13'!AM18+'14'!AM18+'15'!AM18+'16'!AM18+'17'!AM18+'18'!AM18+'19'!AM18+'20'!AM18+'21'!AM18+'22'!AM18+'23'!AM18+'24'!AM18+'25'!AM18+'26'!AM18+'27'!AM18+'28'!AM18+'29'!AM18+'30'!AM18+'31'!AM18 -> 0 | O25: =+'1'!AN18+'2'!AN18+'3'!AN18+'4'!AN18+'5'!AN18+'6'!AN18+'7'!AN18+'8'!AN18+'9'!AN18+'10'!AN18+'11'!AN18+'12'!AN18+'13'!AN18+'14'!AN18+'15'!AN18+'16'!AN18+'17'!AN18+'18'!AN18+'19'!AN18+'20'!AN18+'21'!AN18+'22'!AN18+'23'!AN18+'24'!AN18+'25'!AN18+'26'!AN18+'27'!AN18+'28'!AN18+'29'!AN18+'30'!AN18+'31'!AN18 -> 0 | P25: =+'1'!AO18+'2'!AO18+'3'!AO18+'4'!AO18+'5'!AO18+'6'!AO18+'7'!AO18+'8'!AO18+'9'!AO18+'10'!AO18+'11'!AO18+'12'!AO18+'13'!AO18+'14'!AO18+'15'!AO18+'16'!AO18+'17'!AO18+'18'!AO18+'19'!AO18+'20'!AO18+'21'!AO18+'22'!AO18+'23'!AO18+'24'!AO18+'25'!AO18+'26'!AO18+'27'!AO18+'28'!AO18+'29'!AO18+'30'!AO18+'31'!AO18 -> 0 | ... W25: =+'1'!AV18+'2'!AV18+'3'!AV18+'4'!AV18+'5'!AV18+'6'!AV18+'7'!AV18+'8'!AV18+'9'!AV18+'10'!AV18+'11'!AV18+'12'!AV18+'13'!AV18+'14'!AV18+'15'!AV18+'16'!AV18+'17'!AV18+'18'!AV18+'19'!AV18+'20'!AV18+'21'!AV18+'22'!AV18+'23'!AV18+'24'!AV18+'25'!AV18+'26'!AV18+'27'!AV18+'28'!AV18+'29'!AV18+'30'!AV18+'31'!AV18 -> 0
C26: 제네시스 | D26: JW1 PE | E26: =+'1'!AD19+'2'!AD19+'3'!AD19+'4'!AD19+'5'!AD19+'6'!AD19+'7'!AD19+'8'!AD19+'9'!AD19+'10'!AD19+'11'!AD19+'12'!AD19+'13'!AD19+'14'!AD19+'15'!AD19+'16'!AD19+'17'!AD19+'18'!AD19+'19'!AD19+'20'!AD19+'21'!AD19+'22'!AD19+'23'!AD19+'24'!AD19+'25'!AD19+'26'!AD19+'27'!AD19+'28'!AD19+'29'!AD19+'30'!AD19+'31'!AD19 -> 1837 | F26: =+'1'!AE19+'2'!AE19+'3'!AE19+'4'!AE19+'5'!AE19+'6'!AE19+'7'!AE19+'8'!AE19+'9'!AE19+'10'!AE19+'11'!AE19+'12'!AE19+'13'!AE19+'14'!AE19+'15'!AE19+'16'!AE19+'17'!AE19+'18'!AE19+'19'!AE19+'20'!AE19+'21'!AE19+'22'!AE19+'23'!AE19+'24'!AE19+'25'!AE19+'26'!AE19+'27'!AE19+'28'!AE19+'29'!AE19+'30'!AE19+'31'!AE19 -> 1710 | G26: =+'1'!AF19+'2'!AF19+'3'!AF19+'4'!AF19+'5'!AF19+'6'!AF19+'7'!AF19+'8'!AF19+'9'!AF19+'10'!AF19+'11'!AF19+'12'!AF19+'13'!AF19+'14'!AF19+'15'!AF19+'16'!AF19+'17'!AF19+'18'!AF19+'19'!AF19+'20'!AF19+'21'!AF19+'22'!AF19+'23'!AF19+'24'!AF19+'25'!AF19+'26'!AF19+'27'!AF19+'28'!AF19+'29'!AF19+'30'!AF19+'31'!AF19 -> 127 | H26: =IF(E26=0,"",G26/E26) -> 0.069134458 | I26: =+'1'!AH19+'2'!AH19+'3'!AH19+'4'!AH19+'5'!AH19+'6'!AH19+'7'!AH19+'8'!AH19+'9'!AH19+'10'!AH19+'11'!AH19+'12'!AH19+'13'!AH19+'14'!AH19+'15'!AH19+'16'!AH19+'17'!AH19+'18'!AH19+'19'!AH19+'20'!AH19+'21'!AH19+'22'!AH19+'23'!AH19+'24'!AH19+'25'!AH19+'26'!AH19+'27'!AH19+'28'!AH19+'29'!AH19+'30'!AH19+'31'!AH19 -> 1 | J26: =+'1'!AI19+'2'!AI19+'3'!AI19+'4'!AI19+'5'!AI19+'6'!AI19+'7'!AI19+'8'!AI19+'9'!AI19+'10'!AI19+'11'!AI19+'12'!AI19+'13'!AI19+'14'!AI19+'15'!AI19+'16'!AI19+'17'!AI19+'18'!AI19+'19'!AI19+'20'!AI19+'21'!AI19+'22'!AI19+'23'!AI19+'24'!AI19+'25'!AI19+'26'!AI19+'27'!AI19+'28'!AI19+'29'!AI19+'30'!AI19+'31'!AI19 -> 11 | K26: =+'1'!AJ19+'2'!AJ19+'3'!AJ19+'4'!AJ19+'5'!AJ19+'6'!AJ19+'7'!AJ19+'8'!AJ19+'9'!AJ19+'10'!AJ19+'11'!AJ19+'12'!AJ19+'13'!AJ19+'14'!AJ19+'15'!AJ19+'16'!AJ19+'17'!AJ19+'18'!AJ19+'19'!AJ19+'20'!AJ19+'21'!AJ19+'22'!AJ19+'23'!AJ19+'24'!AJ19+'25'!AJ19+'26'!AJ19+'27'!AJ19+'28'!AJ19+'29'!AJ19+'30'!AJ19+'31'!AJ19 -> 0 | L26: =+'1'!AK19+'2'!AK19+'3'!AK19+'4'!AK19+'5'!AK19+'6'!AK19+'7'!AK19+'8'!AK19+'9'!AK19+'10'!AK19+'11'!AK19+'12'!AK19+'13'!AK19+'14'!AK19+'15'!AK19+'16'!AK19+'17'!AK19+'18'!AK19+'19'!AK19+'20'!AK19+'21'!AK19+'22'!AK19+'23'!AK19+'24'!AK19+'25'!AK19+'26'!AK19+'27'!AK19+'28'!AK19+'29'!AK19+'30'!AK19+'31'!AK19 -> 0 | M26: =+'1'!AL19+'2'!AL19+'3'!AL19+'4'!AL19+'5'!AL19+'6'!AL19+'7'!AL19+'8'!AL19+'9'!AL19+'10'!AL19+'11'!AL19+'12'!AL19+'13'!AL19+'14'!AL19+'15'!AL19+'16'!AL19+'17'!AL19+'18'!AL19+'19'!AL19+'20'!AL19+'21'!AL19+'22'!AL19+'23'!AL19+'24'!AL19+'25'!AL19+'26'!AL19+'27'!AL19+'28'!AL19+'29'!AL19+'30'!AL19+'31'!AL19 -> 0 | N26: =+'1'!AM19+'2'!AM19+'3'!AM19+'4'!AM19+'5'!AM19+'6'!AM19+'7'!AM19+'8'!AM19+'9'!AM19+'10'!AM19+'11'!AM19+'12'!AM19+'13'!AM19+'14'!AM19+'15'!AM19+'16'!AM19+'17'!AM19+'18'!AM19+'19'!AM19+'20'!AM19+'21'!AM19+'22'!AM19+'23'!AM19+'24'!AM19+'25'!AM19+'26'!AM19+'27'!AM19+'28'!AM19+'29'!AM19+'30'!AM19+'31'!AM19 -> 0 | O26: =+'1'!AN19+'2'!AN19+'3'!AN19+'4'!AN19+'5'!AN19+'6'!AN19+'7'!AN19+'8'!AN19+'9'!AN19+'10'!AN19+'11'!AN19+'12'!AN19+'13'!AN19+'14'!AN19+'15'!AN19+'16'!AN19+'17'!AN19+'18'!AN19+'19'!AN19+'20'!AN19+'21'!AN19+'22'!AN19+'23'!AN19+'24'!AN19+'25'!AN19+'26'!AN19+'27'!AN19+'28'!AN19+'29'!AN19+'30'!AN19+'31'!AN19 -> 0 | P26: =+'1'!AO19+'2'!AO19+'3'!AO19+'4'!AO19+'5'!AO19+'6'!AO19+'7'!AO19+'8'!AO19+'9'!AO19+'10'!AO19+'11'!AO19+'12'!AO19+'13'!AO19+'14'!AO19+'15'!AO19+'16'!AO19+'17'!AO19+'18'!AO19+'19'!AO19+'20'!AO19+'21'!AO19+'22'!AO19+'23'!AO19+'24'!AO19+'25'!AO19+'26'!AO19+'27'!AO19+'28'!AO19+'29'!AO19+'30'!AO19+'31'!AO19 -> 0 | ... W26: =+'1'!AV19+'2'!AV19+'3'!AV19+'4'!AV19+'5'!AV19+'6'!AV19+'7'!AV19+'8'!AV19+'9'!AV19+'10'!AV19+'11'!AV19+'12'!AV19+'13'!AV19+'14'!AV19+'15'!AV19+'16'!AV19+'17'!AV19+'18'!AV19+'19'!AV19+'20'!AV19+'21'!AV19+'22'!AV19+'23'!AV19+'24'!AV19+'25'!AV19+'26'!AV19+'27'!AV19+'28'!AV19+'29'!AV19+'30'!AV19+'31'!AV19 -> 2
C27: B | D27: 나 | E27: =+'1'!AD20+'2'!AD20+'3'!AD20+'4'!AD20+'5'!AD20+'6'!AD20+'7'!AD20+'8'!AD20+'9'!AD20+'10'!AD20+'11'!AD20+'12'!AD20+'13'!AD20+'14'!AD20+'15'!AD20+'16'!AD20+'17'!AD20+'18'!AD20+'19'!AD20+'20'!AD20+'21'!AD20+'22'!AD20+'23'!AD20+'24'!AD20+'25'!AD20+'26'!AD20+'27'!AD20+'28'!AD20+'29'!AD20+'30'!AD20+'31'!AD20 -> 0 | F27: =+'1'!AE20+'2'!AE20+'3'!AE20+'4'!AE20+'5'!AE20+'6'!AE20+'7'!AE20+'8'!AE20+'9'!AE20+'10'!AE20+'11'!AE20+'12'!AE20+'13'!AE20+'14'!AE20+'15'!AE20+'16'!AE20+'17'!AE20+'18'!AE20+'19'!AE20+'20'!AE20+'21'!AE20+'22'!AE20+'23'!AE20+'24'!AE20+'25'!AE20+'26'!AE20+'27'!AE20+'28'!AE20+'29'!AE20+'30'!AE20+'31'!AE20 -> 0 | G27: =+'1'!AF20+'2'!AF20+'3'!AF20+'4'!AF20+'5'!AF20+'6'!AF20+'7'!AF20+'8'!AF20+'9'!AF20+'10'!AF20+'11'!AF20+'12'!AF20+'13'!AF20+'14'!AF20+'15'!AF20+'16'!AF20+'17'!AF20+'18'!AF20+'19'!AF20+'20'!AF20+'21'!AF20+'22'!AF20+'23'!AF20+'24'!AF20+'25'!AF20+'26'!AF20+'27'!AF20+'28'!AF20+'29'!AF20+'30'!AF20+'31'!AF20 -> 0 | H27: =IF(E27=0,"",G27/E27) | I27: =+'1'!AH20+'2'!AH20+'3'!AH20+'4'!AH20+'5'!AH20+'6'!AH20+'7'!AH20+'8'!AH20+'9'!AH20+'10'!AH20+'11'!AH20+'12'!AH20+'13'!AH20+'14'!AH20+'15'!AH20+'16'!AH20+'17'!AH20+'18'!AH20+'19'!AH20+'20'!AH20+'21'!AH20+'22'!AH20+'23'!AH20+'24'!AH20+'25'!AH20+'26'!AH20+'27'!AH20+'28'!AH20+'29'!AH20+'30'!AH20+'31'!AH20 -> 0 | J27: =+'1'!AI20+'2'!AI20+'3'!AI20+'4'!AI20+'5'!AI20+'6'!AI20+'7'!AI20+'8'!AI20+'9'!AI20+'10'!AI20+'11'!AI20+'12'!AI20+'13'!AI20+'14'!AI20+'15'!AI20+'16'!AI20+'17'!AI20+'18'!AI20+'19'!AI20+'20'!AI20+'21'!AI20+'22'!AI20+'23'!AI20+'24'!AI20+'25'!AI20+'26'!AI20+'27'!AI20+'28'!AI20+'29'!AI20+'30'!AI20+'31'!AI20 -> 0 | K27: =+'1'!AJ20+'2'!AJ20+'3'!AJ20+'4'!AJ20+'5'!AJ20+'6'!AJ20+'7'!AJ20+'8'!AJ20+'9'!AJ20+'10'!AJ20+'11'!AJ20+'12'!AJ20+'13'!AJ20+'14'!AJ20+'15'!AJ20+'16'!AJ20+'17'!AJ20+'18'!AJ20+'19'!AJ20+'20'!AJ20+'21'!AJ20+'22'!AJ20+'23'!AJ20+'24'!AJ20+'25'!AJ20+'26'!AJ20+'27'!AJ20+'28'!AJ20+'29'!AJ20+'30'!AJ20+'31'!AJ20 -> 0 | L27: =+'1'!AK20+'2'!AK20+'3'!AK20+'4'!AK20+'5'!AK20+'6'!AK20+'7'!AK20+'8'!AK20+'9'!AK20+'10'!AK20+'11'!AK20+'12'!AK20+'13'!AK20+'14'!AK20+'15'!AK20+'16'!AK20+'17'!AK20+'18'!AK20+'19'!AK20+'20'!AK20+'21'!AK20+'22'!AK20+'23'!AK20+'24'!AK20+'25'!AK20+'26'!AK20+'27'!AK20+'28'!AK20+'29'!AK20+'30'!AK20+'31'!AK20 -> 0 | M27: =+'1'!AL20+'2'!AL20+'3'!AL20+'4'!AL20+'5'!AL20+'6'!AL20+'7'!AL20+'8'!AL20+'9'!AL20+'10'!AL20+'11'!AL20+'12'!AL20+'13'!AL20+'14'!AL20+'15'!AL20+'16'!AL20+'17'!AL20+'18'!AL20+'19'!AL20+'20'!AL20+'21'!AL20+'22'!AL20+'23'!AL20+'24'!AL20+'25'!AL20+'26'!AL20+'27'!AL20+'28'!AL20+'29'!AL20+'30'!AL20+'31'!AL20 -> 0 | N27: =+'1'!AM20+'2'!AM20+'3'!AM20+'4'!AM20+'5'!AM20+'6'!AM20+'7'!AM20+'8'!AM20+'9'!AM20+'10'!AM20+'11'!AM20+'12'!AM20+'13'!AM20+'14'!AM20+'15'!AM20+'16'!AM20+'17'!AM20+'18'!AM20+'19'!AM20+'20'!AM20+'21'!AM20+'22'!AM20+'23'!AM20+'24'!AM20+'25'!AM20+'26'!AM20+'27'!AM20+'28'!AM20+'29'!AM20+'30'!AM20+'31'!AM20 -> 0 | O27: =+'1'!AN20+'2'!AN20+'3'!AN20+'4'!AN20+'5'!AN20+'6'!AN20+'7'!AN20+'8'!AN20+'9'!AN20+'10'!AN20+'11'!AN20+'12'!AN20+'13'!AN20+'14'!AN20+'15'!AN20+'16'!AN20+'17'!AN20+'18'!AN20+'19'!AN20+'20'!AN20+'21'!AN20+'22'!AN20+'23'!AN20+'24'!AN20+'25'!AN20+'26'!AN20+'27'!AN20+'28'!AN20+'29'!AN20+'30'!AN20+'31'!AN20 -> 0 | P27: =+'1'!AO20+'2'!AO20+'3'!AO20+'4'!AO20+'5'!AO20+'6'!AO20+'7'!AO20+'8'!AO20+'9'!AO20+'10'!AO20+'11'!AO20+'12'!AO20+'13'!AO20+'14'!AO20+'15'!AO20+'16'!AO20+'17'!AO20+'18'!AO20+'19'!AO20+'20'!AO20+'21'!AO20+'22'!AO20+'23'!AO20+'24'!AO20+'25'!AO20+'26'!AO20+'27'!AO20+'28'!AO20+'29'!AO20+'30'!AO20+'31'!AO20 -> 0 | ... W27: =+'1'!AV20+'2'!AV20+'3'!AV20+'4'!AV20+'5'!AV20+'6'!AV20+'7'!AV20+'8'!AV20+'9'!AV20+'10'!AV20+'11'!AV20+'12'!AV20+'13'!AV20+'14'!AV20+'15'!AV20+'16'!AV20+'17'!AV20+'18'!AV20+'19'!AV20+'20'!AV20+'21'!AV20+'22'!AV20+'23'!AV20+'24'!AV20+'25'!AV20+'26'!AV20+'27'!AV20+'28'!AV20+'29'!AV20+'30'!AV20+'31'!AV20 -> 0
